Workbook

Sheet 00_START
A1: EQUIL LIGHT — PORNIRE
A2: Varianta pentru firme mici. Completezi doar celulele galbene; cele gri se calculează singure.
A4: PENTRU CINE E
A5: Potrivit | B5: Firme sub 10 angajați, până în ~500.000 lei pe an, sub 100 de clienți, fără ERP și fără CRM. Adică: facturează dintr-un program simplu sau din Word, și ține minte clienții pe de rost.
A6: Nepotrivit | B6: Dacă firma are ERP, echipă de vânzări cu ținte individuale și peste 100 de clienți, folosește varianta completă — acolo ai analiză pe produse, pe oameni și pe ținte.
A7: Se poate trece | B7: Datele de aici sunt un subset al variantei complete. Dacă firma crește, se mută coloanele și nu pierzi nimic din istoric.
A9: CE CERI DE LA CLIENT
A10: Un singur lucru | B10: Exportul facturilor pe ultimele 24 de luni, în Excel sau CSV, cu: data, clientul, ce a cumpărat și suma fără TVA.
A11: Al doilea lucru | B11: Costul direct pentru fiecare vânzare — cât l-a costat marfa sau materialul. Dacă nu îl are pe linie, cere-i un procent mediu și calculezi tu.
A12: Dacă nu poate exporta | B12: Nu e capăt de drum. Ia ultimele 12 luni din facturier și tastează-le. La 100.000 € pe an înseamnă câteva sute de linii, adică o după-amiază.
A13: De la cine | B13: La o firmă mică sunt doi oameni: patronul (context, obiective) și contabilul (facturi, costuri). Nu ai nevoie de mai mult.
A15: ORDINEA DE LUCRU
A16: 1. 01_FIRMA | B16: 14 rânduri, în discuția de început. 15 minute.
A17: 2. 11_CLIENTI | B17: Scrie lista de clienți. Notele le poți adăuga mai târziu, după ce suni. 20 de minute.
A18: 3. 10_VANZARI | B18: Lipește sau tastează vânzările. Aici se duce timpul: 30 de minute până la 2 ore.
A19: 4. 02_SETARI | B19: Perioada și obiectivul. 5 minute.
A20: 5. 20_REZULTATE | B20: Citești cifrele și concluziile. Nu scrii nimic. 15 minute.
A21: 6. 21_CE_SE_INTAMPLA | B21: Vezi ce se întâmplă cu fiecare client și ce ai de făcut. 20 de minute.
A22: 7. 30_PLAN | B22: Alegi maximum zece acțiuni. Primele trei sunt cele de acum. 20 de minute.
A23: 8. 40_GRAFICE | B23: Trei grafice, pentru discuția cu clientul. Se desenează singure.
A24: Total | B24: Aproximativ 2 ore de lucru, dacă datele vin curate. Jumătate din varianta completă.
A26: TREI REGULI
A27: Sumele fără TVA | B27: Toate. Dacă amesteci, cifrele ies greșite cu 19% și nu îți dai seama.
A28: Numele clientului la fel | B28: De asta îl alegi din listă în 10_VANZARI, în loc să îl scrii de fiecare dată.
A29: Costul direct, nu toate costurile | B29: Marfa și materialul intră. Chiria și contabilul nu — acelea se scad din profitul brut, mai încolo.
A31: CULORI
A32: Galben | B32: Scrii tu.
A33: Gri | B33: Se calculează singur. Dacă scrii peste, strici calculul și nu te anunță nimeni.

Sheet 01_FIRMA
A1: 01 — DESPRE FIRMĂ
A2: Paisprezece rânduri, completate în discuția de început. Restul se vede din cifre.
A4: Cod client EQUIL | C4: ID-ul tău intern: EQ-0001, EQ-0002…
A5: Denumirea firmei
A6: CUI
A7: Ce vinde, pe scurt | C7: O propoziție, în cuvintele lui.
A8: Câți oameni lucrează acolo | C8: Cu tot cu patron.
A9: Cifra de afaceri anul trecut | C9: Fără TVA. Aproximativ e suficient.
A10: Câți clienți are, aproximativ
A11: Cum emite facturile | C11: Smartbill, Oblio, FGO, Word, carnet — orice ar fi.
A12: Poate exporta facturile în Excel? | C12: Da / Nu / Nu știu. De asta depinde cât durează totul.
A13: Ce vrea să obțină în 12 luni | C13: În cifre, dacă se poate.
A14: Ce îl supără cel mai tare acum | C14: De obicei aici e adevărata problemă.
A15: Cine decide | C15: Numele omului care semnează.
A16: Perioada pe care o analizăm | C16: Trebuie să fie aceeași ca în 02_SETARI.
A17: Data discuției

Sheet 02_SETARI
A1: 02 — SETĂRI
A2: Cinci lucruri de stabilit o singură dată. Tot fișierul se recalculează din ele.
A4: PERIOADA | E4: — liste (nu se șterg) —
A5: Analizez de la | B5: 46023 | C5: Prima zi a perioadei. | E5: Segment | F5: Status plan | H5: Monedă
A6: Analizez până la | B6: 46203 | C6: Ultima zi a perioadei. | E6: Client mare | F6: De făcut | H6: RON
A7: Compar cu — de la | B7: 45658 | C7: De obicei aceeași perioadă de anul trecut. Dacă firma e prea nouă, lasă perioada anterioară. | E7: Client mediu | F7: În lucru | H7: EUR
A8: Compar cu — până la | B8: 45838 | E8: Client mic | F8: Gata | H8: USD
A9: Monedă | B9: RON | C9: Toate sumele din fișier trebuie să fie în aceeași monedă. | E9: Ocazional | F9: Renunțat
A11: OBIECTIV
A12: Cât își propune să vândă în perioadă | B12: 0 | C12: Un singur număr. Dacă nu are un buget, întreabă-l „cât ți-ai dori?” și scrie cifra aceea.
A14: PRAGURI (le poți lăsa așa)
A15: Scădere care mă îngrijorează | B15: -0.15 | C15: Sub această variație față de perioada comparativă, clientul apare ca „a scăzut”.
A16: Marjă normală în domeniu | B16: 0.3 | C16: Sub ea, apare semnalul de marjă mică. Întreabă-l pe client cât e normal la el.
A17: Zile fără comandă = client adormit | B17: 90 | C17: Pentru servicii recurente, pune mai puțin. Pentru vânzări rare, mai mult.
A18: Sub ce notă e client nemulțumit | B18: 6 | C18: Pe scara 0-10. Nota 6 sau mai mică înseamnă nemulțumit.
A19: Data de referință | B19: =IF($B$6="",TODAY(),$B$6) | C19: Față de ea se numără zilele fără comandă. Implicit, ultima zi a perioadei.

Sheet 10_VANZARI
A1: 10 — VÂNZĂRI
A2: Singura foaie în care intră volum de date. O linie = o factură (sau o lună, dacă facturezi lunar același lucru). Coloanele gri se calculează singure.
A4: Data | B4: Client | C4: Ce a cumpărat | D4: Cantitate | E4: Încasat (fără TVA) | F4: Cât te-a costat | G4: Profit brut | H4: Marjă | I4: Lună | J4: Observații
A5: 46053 | B5: Exemplu SRL | C5: Exemplu — șterge rândul | E5: 1000 | F5: 600 | G5: =IF($E5="","",$E5-N($F5)) | H5: =IFERROR($G5/$E5,"") | I5: =IF($A5="","",YEAR($A5)&"-"&RIGHT("0"&MONTH($A5),2))
G6: =IF($E6="","",$E6-N($F6)) | H6: =IFERROR($G6/$E6,"") | I6: =IF($A6="","",YEAR($A6)&"-"&RIGHT("0"&MONTH($A6),2))
G7: =IF($E7="","",$E7-N($F7)) | H7: =IFERROR($G7/$E7,"") | I7: =IF($A7="","",YEAR($A7)&"-"&RIGHT("0"&MONTH($A7),2))
G8: =IF($E8="","",$E8-N($F8)) | H8: =IFERROR($G8/$E8,"") | I8: =IF($A8="","",YEAR($A8)&"-"&RIGHT("0"&MONTH($A8),2))
G9: =IF($E9="","",$E9-N($F9)) | H9: =IFERROR($G9/$E9,"") | I9: =IF($A9="","",YEAR($A9)&"-"&RIGHT("0"&MONTH($A9),2))
G10: =IF($E10="","",$E10-N($F10)) | H10: =IFERROR($G10/$E10,"") | I10: =IF($A10="","",YEAR($A10)&"-"&RIGHT("0"&MONTH($A10),2))
G11: =IF($E11="","",$E11-N($F11)) | H11: =IFERROR($G11/$E11,"") | I11: =IF($A11="","",YEAR($A11)&"-"&RIGHT("0"&MONTH($A11),2))
G12: =IF($E12="","",$E12-N($F12)) | H12: =IFERROR($G12/$E12,"") | I12: =IF($A12="","",YEAR($A12)&"-"&RIGHT("0"&MONTH($A12),2))
G13: =IF($E13="","",$E13-N($F13)) | H13: =IFERROR($G13/$E13,"") | I13: =IF($A13="","",YEAR($A13)&"-"&RIGHT("0"&MONTH($A13),2))
G14: =IF($E14="","",$E14-N($F14)) | H14: =IFERROR($G14/$E14,"") | I14: =IF($A14="","",YEAR($A14)&"-"&RIGHT("0"&MONTH($A14),2))
G15: =IF($E15="","",$E15-N($F15)) | H15: =IFERROR($G15/$E15,"") | I15: =IF($A15="","",YEAR($A15)&"-"&RIGHT("0"&MONTH($A15),2))
G16: =IF($E16="","",$E16-N($F16)) | H16: =IFERROR($G16/$E16,"") | I16: =IF($A16="","",YEAR($A16)&"-"&RIGHT("0"&MONTH($A16),2))
G17: =IF($E17="","",$E17-N($F17)) | H17: =IFERROR($G17/$E17,"") | I17: =IF($A17="","",YEAR($A17)&"-"&RIGHT("0"&MONTH($A17),2))
... G604: =IF($E604="","",$E604-N($F604)) | H604: =IFERROR($G604/$E604,"") | I604: =IF($A604="","",YEAR($A604)&"-"&RIGHT("0"&MONTH($A604),2))

Sheet 11_CLIENTI
A1: 11 — CLIENȚII
A2: Lista clienților. Se scrie o dată, la început. Nota din coloana D se ia sunându-i — pentru o firmă mică e realist să-i întrebi pe toți.
A4: Client | B4: Segment | C4: Client din | D4: Notă 0-10 | E4: Ce a spus | F4: Data întrebării | G4: Observații
A5: Exemplu SRL | B5: Client mare | E5: Exemplu — șterge rândul înainte de utilizare

Sheet 12_CONCURENTA
A1: 12 — CONCURENȚA | Y1: surse_cifra | Z1: pret
A2: Primul rând ești tu (firma analizată). Sub el, concurenții. Cifrele publice și notele se adună de pe internet într-o oră, fără să întrebi pe nimeni. | Y2: Date publice / bilanț | Z2: Mult mai ieftin
Y3: Estimare proprie | Z3: Mai ieftin
A4: Cine | B4: Site | C4: Angajați | D4: Cifră de afaceri | E4: De unde e cifra | F4: Notă publică (1-5) | G4: Câte recenzii | H4: Verificat la data | I4: Preț față de noi | J4: Cu ce câștigă | K4: Unde pierde | L4: Cotă în grup | M4: Cum stăm față de el | O4: CUM ARATĂ PIAȚA | Y4: Spus de client | Z4: La fel
A5: NOI (firma analizată) | L5: =IF($A5="","",IFERROR($D5/SUM('12_CONCURENTA'!$D$5:$D$14),"")) | M5: =IF($A5="","",IF(ROW()=5,"— reper —",IF(AND($F5<>"",'12_CONCURENTA'!$F$5<>""),IF($F5>'12_CONCURENTA'!$F$5+0.2,"E mai bine văzut",IF($F5<'12_CONCURENTA'!$F$5-0.2,"Suntem mai bine văzuți","Văzuți la fel")),"Fără notă")&IF(AND($D5<>"",'12_CONCURENTA'!$D$5<>"",'12_CONCURENTA'!$D$5>0),IF($D5>'12_CONCURENTA'!$D$5*1.2," · mai mare",IF($D5<'12_CONCURENTA'!$D$5*0.8," · mai mic"," · cam cât noi")),""))) | O5: Concurenți urmăriți | P5: =MAX(0,COUNTA('12_CONCURENTA'!$A$5:$A$14)-1) | Y5: Site / presă | Z5: Mai scump
L6: =IF($A6="","",IFERROR($D6/SUM('12_CONCURENTA'!$D$5:$D$14),"")) | M6: =IF($A6="","",IF(ROW()=5,"— reper —",IF(AND($F6<>"",'12_CONCURENTA'!$F$5<>""),IF($F6>'12_CONCURENTA'!$F$5+0.2,"E mai bine văzut",IF($F6<'12_CONCURENTA'!$F$5-0.2,"Suntem mai bine văzuți","Văzuți la fel")),"Fără notă")&IF(AND($D6<>"",'12_CONCURENTA'!$D$5<>"",'12_CONCURENTA'!$D$5>0),IF($D6>'12_CONCURENTA'!$D$5*1.2," · mai mare",IF($D6<'12_CONCURENTA'!$D$5*0.8," · mai mic"," · cam cât noi")),""))) | O6: Cifra totală a grupului | P6: =SUM('12_CONCURENTA'!$D$5:$D$14) | Y6: Nu știu | Z6: Mult mai scump
L7: =IF($A7="","",IFERROR($D7/SUM('12_CONCURENTA'!$D$5:$D$14),"")) | M7: =IF($A7="","",IF(ROW()=5,"— reper —",IF(AND($F7<>"",'12_CONCURENTA'!$F$5<>""),IF($F7>'12_CONCURENTA'!$F$5+0.2,"E mai bine văzut",IF($F7<'12_CONCURENTA'!$F$5-0.2,"Suntem mai bine văzuți","Văzuți la fel")),"Fără notă")&IF(AND($D7<>"",'12_CONCURENTA'!$D$5<>"",'12_CONCURENTA'!$D$5>0),IF($D7>'12_CONCURENTA'!$D$5*1.2," · mai mare",IF($D7<'12_CONCURENTA'!$D$5*0.8," · mai mic"," · cam cât noi")),""))) | O7: Cota noastră în grup | P7: =IFERROR('12_CONCURENTA'!$D$5/SUM('12_CONCURENTA'!$D$5:$D$14),"") | Z7: Nu știu
L8: =IF($A8="","",IFERROR($D8/SUM('12_CONCURENTA'!$D$5:$D$14),"")) | M8: =IF($A8="","",IF(ROW()=5,"— reper —",IF(AND($F8<>"",'12_CONCURENTA'!$F$5<>""),IF($F8>'12_CONCURENTA'!$F$5+0.2,"E mai bine văzut",IF($F8<'12_CONCURENTA'!$F$5-0.2,"Suntem mai bine văzuți","Văzuți la fel")),"Fără notă")&IF(AND($D8<>"",'12_CONCURENTA'!$D$5<>"",'12_CONCURENTA'!$D$5>0),IF($D8>'12_CONCURENTA'!$D$5*1.2," · mai mare",IF($D8<'12_CONCURENTA'!$D$5*0.8," · mai mic"," · cam cât noi")),""))) | O8: Piața totală estimată | P8: 0 | Q8: Opțional. Dacă știi cât valorează toată piața, aici iese cota reală.
L9: =IF($A9="","",IFERROR($D9/SUM('12_CONCURENTA'!$D$5:$D$14),"")) | M9: =IF($A9="","",IF(ROW()=5,"— reper —",IF(AND($F9<>"",'12_CONCURENTA'!$F$5<>""),IF($F9>'12_CONCURENTA'!$F$5+0.2,"E mai bine văzut",IF($F9<'12_CONCURENTA'!$F$5-0.2,"Suntem mai bine văzuți","Văzuți la fel")),"Fără notă")&IF(AND($D9<>"",'12_CONCURENTA'!$D$5<>"",'12_CONCURENTA'!$D$5>0),IF($D9>'12_CONCURENTA'!$D$5*1.2," · mai mare",IF($D9<'12_CONCURENTA'!$D$5*0.8," · mai mic"," · cam cât noi")),""))) | O9: Cota noastră din piață | P9: =IF(OR('12_CONCURENTA'!$P$8=0,'12_CONCURENTA'!$P$8=""),"",IFERROR('12_CONCURENTA'!$D$5/'12_CONCURENTA'!$P$8,""))
L10: =IF($A10="","",IFERROR($D10/SUM('12_CONCURENTA'!$D$5:$D$14),"")) | M10: =IF($A10="","",IF(ROW()=5,"— reper —",IF(AND($F10<>"",'12_CONCURENTA'!$F$5<>""),IF($F10>'12_CONCURENTA'!$F$5+0.2,"E mai bine văzut",IF($F10<'12_CONCURENTA'!$F$5-0.2,"Suntem mai bine văzuți","Văzuți la fel")),"Fără notă")&IF(AND($D10<>"",'12_CONCURENTA'!$D$5<>"",'12_CONCURENTA'!$D$5>0),IF($D10>'12_CONCURENTA'!$D$5*1.2," · mai mare",IF($D10<'12_CONCURENTA'!$D$5*0.8," · mai mic"," · cam cât noi")),""))) | O10: Nota noastră publică | P10: =IF('12_CONCURENTA'!$F$5="","",'12_CONCURENTA'!$F$5)
L11: =IF($A11="","",IFERROR($D11/SUM('12_CONCURENTA'!$D$5:$D$14),"")) | M11: =IF($A11="","",IF(ROW()=5,"— reper —",IF(AND($F11<>"",'12_CONCURENTA'!$F$5<>""),IF($F11>'12_CONCURENTA'!$F$5+0.2,"E mai bine văzut",IF($F11<'12_CONCURENTA'!$F$5-0.2,"Suntem mai bine văzuți","Văzuți la fel")),"Fără notă")&IF(AND($D11<>"",'12_CONCURENTA'!$D$5<>"",'12_CONCURENTA'!$D$5>0),IF($D11>'12_CONCURENTA'!$D$5*1.2," · mai mare",IF($D11<'12_CONCURENTA'!$D$5*0.8," · mai mic"," · cam cât noi")),""))) | O11: Nota medie a concurenților | P11: =IFERROR(AVERAGE('12_CONCURENTA'!$F$6:$F$14),"")
L12: =IF($A12="","",IFERROR($D12/SUM('12_CONCURENTA'!$D$5:$D$14),"")) | M12: =IF($A12="","",IF(ROW()=5,"— reper —",IF(AND($F12<>"",'12_CONCURENTA'!$F$5<>""),IF($F12>'12_CONCURENTA'!$F$5+0.2,"E mai bine văzut",IF($F12<'12_CONCURENTA'!$F$5-0.2,"Suntem mai bine văzuți","Văzuți la fel")),"Fără notă")&IF(AND($D12<>"",'12_CONCURENTA'!$D$5<>"",'12_CONCURENTA'!$D$5>0),IF($D12>'12_CONCURENTA'!$D$5*1.2," · mai mare",IF($D12<'12_CONCURENTA'!$D$5*0.8," · mai mic"," · cam cât noi")),""))) | O12: Diferența | P12: =IF(OR('12_CONCURENTA'!$F$5="",P11=""),"",'12_CONCURENTA'!$F$5-P11)
L13: =IF($A13="","",IFERROR($D13/SUM('12_CONCURENTA'!$D$5:$D$14),"")) | M13: =IF($A13="","",IF(ROW()=5,"— reper —",IF(AND($F13<>"",'12_CONCURENTA'!$F$5<>""),IF($F13>'12_CONCURENTA'!$F$5+0.2,"E mai bine văzut",IF($F13<'12_CONCURENTA'!$F$5-0.2,"Suntem mai bine văzuți","Văzuți la fel")),"Fără notă")&IF(AND($D13<>"",'12_CONCURENTA'!$D$5<>"",'12_CONCURENTA'!$D$5>0),IF($D13>'12_CONCURENTA'!$D$5*1.2," · mai mare",IF($D13<'12_CONCURENTA'!$D$5*0.8," · mai mic"," · cam cât noi")),"")))
L14: =IF($A14="","",IFERROR($D14/SUM('12_CONCURENTA'!$D$5:$D$14),"")) | M14: =IF($A14="","",IF(ROW()=5,"— reper —",IF(AND($F14<>"",'12_CONCURENTA'!$F$5<>""),IF($F14>'12_CONCURENTA'!$F$5+0.2,"E mai bine văzut",IF($F14<'12_CONCURENTA'!$F$5-0.2,"Suntem mai bine văzuți","Văzuți la fel")),"Fără notă")&IF(AND($D14<>"",'12_CONCURENTA'!$D$5<>"",'12_CONCURENTA'!$D$5>0),IF($D14>'12_CONCURENTA'!$D$5*1.2," · mai mare",IF($D14<'12_CONCURENTA'!$D$5*0.8," · mai mic"," · cam cât noi")),"")))

Sheet 13_CE_CRED_OAMENII
A1: 13 — CE CRED OAMENII DESPRE FIRMĂ | Z1: surse
A2: Trei surse, în ordinea efortului: ce se vede public, ce vezi tu ca specialist, ce spun clienții întrebați direct. Ultima e NPS-ul și e singura care contează cu adevărat; primele două țin locul până atunci. | Z2: Google
Z3: Facebook
A4: 1. CE SE VEDE PUBLIC — recenzii, note, platforme | Z4: Site propriu
A5: Sursa | B5: Link | C5: Verificat la | D5: Notă (1-5) | E5: Câte recenzii | F5: Din care 1-2 stele | G5: Cea mai recentă | H5: Ce laudă cel mai des | I5: Ce reclamă cel mai des | J5: Observații | Z5: Trustpilot
A6: Google | Z6: Booking
Z7: eMAG
Z8: Recomandări directe
Z9: Altă platformă
A13: 2. PĂREREA SPECIALISTULUI — zece lucruri pe care le poți verifica singur
A14: Ce verifici | B14: Notă 1-5 | C14: Cine a evaluat | D14: Cum verifici | E14: Ce ai observat concret | H14: Ce s-ar putea face
A15: Se înțelege în 10 secunde ce vinde? | D15: Intră pe site ca un client care nu știe nimic. Dacă nu pricepi în 10 secunde, nici el nu pricepe.
A16: Cât de ușor e de găsit online? | D16: Caută pe Google ce vinde + orașul. Apare? Pe ce poziție? Are fișă Google Business completă?
A17: Cât de repede răspunde la o cerere? | D17: Trimite o cerere reală prin formular sau sună. Cronometrează. Sub o oră e bine, peste o zi e o problemă.
A18: Prima impresie la contact | D18: Cum răspunde la telefon, cum arată magazinul sau biroul, cum arată oferta scrisă.
A19: Prețul, față de ce ai văzut la concurenți | D19: Nu „scump/ieftin”, ci: prețul e justificat de ceva vizibil?
A20: Livrează consecvent ce promite? | D20: Din recenzii și din ce spun clienții: se întâmplă la fel de fiecare dată?
A21: Cât de ușor e să reclami ceva? | D21: Există un om, un număr, un proces? Sau reclamația se pierde?
A22: Cu ce se diferențiază real? | D22: Un lucru pe care concurenții nu îl au. „Calitate” și „seriozitate” nu sunt răspunsuri.
A23: Ce se aude despre ei în piață? | D23: Ce spun furnizorii, partenerii, foștii angajați. Informal, dar util.
A24: Tu, ca specialist, ai recomanda-o unui prieten? | D24: Aceeași întrebare ca la NPS, pusă ție. 1 = în niciun caz, 5 = fără ezitare.
A26: 3. SCORUL DE PERCEPȚIE — cât de bine e văzută firma, fără să întrebi clienții
A27: Nota publică (medie ponderată) | B27: =IFERROR(SUMPRODUCT(('13_CE_CRED_OAMENII'!$D$6:$D$11<>"")*('13_CE_CRED_OAMENII'!$E$6:$E$11<>"")*'13_CE_CRED_OAMENII'!$D$6:$D$11*'13_CE_CRED_OAMENII'!$E$6:$E$11)/SUMPRODUCT(('13_CE_CRED_OAMENII'!$D$6:$D$11<>"")*('13_CE_CRED_OAMENII'!$E$6:$E$11<>"")*'13_CE_CRED_OAMENII'!$E$6:$E$11),"") | D27: Media notelor de pe platforme, ponderată cu numărul de recenzii.
A28: Total recenzii publice | B28: =SUMPRODUCT(('13_CE_CRED_OAMENII'!$D$6:$D$11<>"")*'13_CE_CRED_OAMENII'!$E$6:$E$11) | D28: Sub 20 de recenzii, nota publică e orientativă.
A29: Scor din recenzii (0-100) | B29: =IF(IFERROR(SUMPRODUCT(('13_CE_CRED_OAMENII'!$D$6:$D$11<>"")*('13_CE_CRED_OAMENII'!$E$6:$E$11<>"")*'13_CE_CRED_OAMENII'!$D$6:$D$11*'13_CE_CRED_OAMENII'!$E$6:$E$11)/SUMPRODUCT(('13_CE_CRED_OAMENII'!$D$6:$D$11<>"")*('13_CE_CRED_OAMENII'!$E$6:$E$11<>"")*'13_CE_CRED_OAMENII'!$E$6:$E$11),"")="","",(IFERROR(SUMPRODUCT(('13_CE_CRED_OAMENII'!$D$6:$D$11<>"")*('13_CE_CRED_OAMENII'!$E$6:$E$11<>"")*'13_CE_CRED_OAMENII'!$D$6:$D$11*'13_CE_CRED_OAMENII'!$E$6:$E$11)/SUMPRODUCT(('13_CE_CRED_OAMENII'!$D$6:$D$11<>"")*('13_CE_CRED_OAMENII'!$E$6:$E$11<>"")*'13_CE_CRED_OAMENII'!$E$6:$E$11),"")-1)/4*100) | D29: Nota publică adusă pe scara 0-100, ca să se poată compara cu restul.
A30: Scor specialist (0-100) | B30: =IF(IFERROR(AVERAGE('13_CE_CRED_OAMENII'!$B$15:$B$24),"")="","",(IFERROR(AVERAGE('13_CE_CRED_OAMENII'!$B$15:$B$24),"")-1)/4*100) | D30: Media celor zece note de mai sus, adusă pe scara 0-100.
A31: SCOR DE PERCEPȚIE | B31: =IF(AND('13_CE_CRED_OAMENII'!$B$29="",'13_CE_CRED_OAMENII'!$B$30=""),"",IF('13_CE_CRED_OAMENII'!$B$29="",'13_CE_CRED_OAMENII'!$B$30,IF('13_CE_CRED_OAMENII'!$B$30="",'13_CE_CRED_OAMENII'!$B$29,('13_CE_CRED_OAMENII'!$B$29+'13_CE_CRED_OAMENII'!$B$30)/2))) | D31: Media celor două de mai sus. NU este NPS — este ce se poate ști fără să întrebi clienții.
A32: Cât te poți baza pe el | B32: =IF(AND('13_CE_CRED_OAMENII'!$B$28=0,COUNT('13_CE_CRED_OAMENII'!$B$15:$B$24)=0),"deloc — nu e completat nimic",IF('13_CE_CRED_OAMENII'!$B$28>=20,IF(COUNT('13_CE_CRED_OAMENII'!$B$15:$B$24)>=8,"bine","parțial — fă și evaluarea de specialist"),IF(COUNT('13_CE_CRED_OAMENII'!$B$15:$B$24)>=8,"parțial — prea puține recenzii publice","slab — completează mai mult"))) | D32: Depinde de câte recenzii sunt și dacă ai făcut evaluarea.
A33: Ce spune diferența | B33: =IF(AND('13_CE_CRED_OAMENII'!$B$29="",'13_CE_CRED_OAMENII'!$B$30=""),"Nu e completată nicio sursă.",IF(AND('13_CE_CRED_OAMENII'!$B$35>=5,'13_CE_CRED_OAMENII'!$B$34<>"",'13_CE_CRED_OAMENII'!$B$31<>"",'13_CE_CRED_OAMENII'!$B$31-(IF('13_CE_CRED_OAMENII'!$B$34="","",('13_CE_CRED_OAMENII'!$B$34+100)/2))>=20),"Publicul larg vede firma mai bine decât o văd clienții ei. Diferența se plătește în reveniri: oamenii cumpără o dată și nu mai revin.",IF(AND('13_CE_CRED_OAMENII'!$B$35>=5,'13_CE_CRED_OAMENII'!$B$34<>"",'13_CE_CRED_OAMENII'!$B$31<>"",(IF('13_CE_CRED_OAMENII'!$B$34="","",('13_CE_CRED_OAMENII'!$B$34+100)/2))-'13_CE_CRED_OAMENII'!$B$31>=20),"Clienții existenți sunt mai mulțumiți decât pare din afară. E o problemă de imagine, nu de livrare — cere-le o recenzie celor mulțumiți.",IF(AND('13_CE_CRED_OAMENII'!$B$29<>"",'13_CE_CRED_OAMENII'!$B$30<>"",'13_CE_CRED_OAMENII'!$B$29-'13_CE_CRED_OAMENII'!$B$30>=20),"Arată mai bine pe internet decât la o verificare atentă. De obicei: recenzii vechi, puține sau cerute selectiv.",IF(AND('13_CE_CRED_OAMENII'!$B$29<>"",'13_CE_CRED_OAMENII'!$B$30<>"",'13_CE_CRED_OAMENII'!$B$30-'13_CE_CRED_OAMENII'!$B$29>=20),"Firma e mai bună decât se vede. Problema e de vizibilitate, nu de calitate — și e mult mai ieftin de rezolvat.","Sursele spun cam același lucru. Te poți baza pe concluzie."))))) | D33: Cele trei surse măsoară lucruri diferite. Când nu sunt de acord, dezacordul e informația.
A34: NPS real (dacă există) | B34: =IFERROR(((SUMPRODUCT(('11_CLIENTI'!$A$5:$A$124<>"")*('11_CLIENTI'!$D$5:$D$124>=9)))-(SUMPRODUCT(('11_CLIENTI'!$A$5:$A$124<>"")*('11_CLIENTI'!$D$5:$D$124<>"")*('11_CLIENTI'!$D$5:$D$124<=6))))/(SUMPRODUCT(('11_CLIENTI'!$A$5:$A$124<>"")*('11_CLIENTI'!$D$5:$D$124<>"")))*100,"") | D34: Din clienții întrebați efectiv. Afișat separat, niciodată amestecat cu scorul de percepție.
A35: Clienți întrebați | B35: =SUMPRODUCT(('11_CLIENTI'!$A$5:$A$124<>"")*('11_CLIENTI'!$D$5:$D$124<>"")) | D35: Câți clienți au dat o notă.
A37: 4. DRUMUL CĂTRE NPS — unde e firma acum și ce urmează
A38: Nivel | B38: Ai? | C38: Cât costă | D38: Ce îți dă
A39: Nivelul 1 — ce se vede public | B39: =IF('13_CE_CRED_OAMENII'!$B$28>0,"Da","Nu încă") | C39: 0 lei, 30 de minute | D39: Nota și recenziile de pe Google. Nu întrebi pe nimeni, dar vezi ce văd clienții noi înainte să sune.
A40: Nivelul 2 — părerea specialistului | B40: =IF(COUNT('13_CE_CRED_OAMENII'!$B$15:$B$24)>=5,"Da","Nu încă") | C40: 0 lei, 1-2 ore | D40: Cele zece verificări de mai sus. Structurate, deci comparabile între firme și în timp.
A41: Nivelul 3 — NPS real | B41: =IF(SUMPRODUCT(('11_CLIENTI'!$A$5:$A$124<>"")*('11_CLIENTI'!$D$5:$D$124<>""))>0,"Da","Nu încă") | C41: 0 lei, 2 ore de telefoane | D41: O singură întrebare, pusă clienților: „de la 0 la 10, cât de probabil ne-ați recomanda?”. Singura care îți spune ce cred clienții tăi, nu ce cred străinii de pe internet.
A43: Următorul pas | B43: =IF('13_CE_CRED_OAMENII'!$B$28=0,"Caută firma pe Google și notează nota și numărul de recenzii, în tabelul de sus. Durează cinci minute și îți arată ce vede un client nou.",IF(COUNT('13_CE_CRED_OAMENII'!$B$15:$B$24)<5,"Fă evaluarea de specialist: cele zece verificări de mai sus. Trimite o cerere reală prin formular și cronometrează răspunsul — de obicei acolo apare prima surpriză.",IF(SUMPRODUCT(('11_CLIENTI'!$A$5:$A$124<>"")*('11_CLIENTI'!$D$5:$D$124<>""))=0,"Ai tot ce se putea afla fără să întrebi clienții. Mai departe nu se poate ghici: sună zece clienți și pune-le o singură întrebare, de la 0 la 10. Două ore de telefoane.",IF(SUMPRODUCT(('11_CLIENTI'!$A$5:$A$124<>"")*('11_CLIENTI'!$D$5:$D$124<>""))<10,"Ai început să întrebi clienții. Mai sună câțiva: sub zece răspunsuri, cifra încă nu e concluzivă.","Ai toate cele trei niveluri. Compară-le: dacă nota publică e mult peste NPS, firma arată mai bine pe internet decât e în relația reală — iar asta se vede în reveniri."))))

Sheet 20_REZULTATE
A1: 20 — REZULTATE
A2: Se completează singură. Nu scrie nimic aici.
A4: CIFRELE
A5: Indicator | B5: Perioada asta | C5: Perioada comparată | D5: Diferență | E5: Ce înseamnă
A6: Încasat (fără TVA) | B6: =SUMIFS('10_VANZARI'!$E$5:$E$604,'10_VANZARI'!$A$5:$A$604,">="&'02_SETARI'!$B$5,'10_VANZARI'!$A$5:$A$604,"<="&'02_SETARI'!$B$6) | C6: =SUMIFS('10_VANZARI'!$E$5:$E$604,'10_VANZARI'!$A$5:$A$604,">="&'02_SETARI'!$B$7,'10_VANZARI'!$A$5:$A$604,"<="&'02_SETARI'!$B$8) | D6: =IFERROR(IF(OR(B6="",C6="",C6="—"),"",B6-C6),"") | E6: Câți bani au intrat din vânzări în perioadă.
A7: Profit brut | B7: =SUMIFS('10_VANZARI'!$G$5:$G$604,'10_VANZARI'!$A$5:$A$604,">="&'02_SETARI'!$B$5,'10_VANZARI'!$A$5:$A$604,"<="&'02_SETARI'!$B$6) | C7: =SUMIFS('10_VANZARI'!$G$5:$G$604,'10_VANZARI'!$A$5:$A$604,">="&'02_SETARI'!$B$7,'10_VANZARI'!$A$5:$A$604,"<="&'02_SETARI'!$B$8) | D7: =IFERROR(IF(OR(B7="",C7="",C7="—"),"",B7-C7),"") | E7: Ce rămâne după costurile directe, înainte de chirie și salarii.
A8: Marjă | B8: =IFERROR(SUMIFS('10_VANZARI'!$G$5:$G$604,'10_VANZARI'!$A$5:$A$604,">="&'02_SETARI'!$B$5,'10_VANZARI'!$A$5:$A$604,"<="&'02_SETARI'!$B$6)/SUMIFS('10_VANZARI'!$E$5:$E$604,'10_VANZARI'!$A$5:$A$604,">="&'02_SETARI'!$B$5,'10_VANZARI'!$A$5:$A$604,"<="&'02_SETARI'!$B$6),0) | C8: =IFERROR(SUMIFS('10_VANZARI'!$G$5:$G$604,'10_VANZARI'!$A$5:$A$604,">="&'02_SETARI'!$B$7,'10_VANZARI'!$A$5:$A$604,"<="&'02_SETARI'!$B$8)/SUMIFS('10_VANZARI'!$E$5:$E$604,'10_VANZARI'!$A$5:$A$604,">="&'02_SETARI'!$B$7,'10_VANZARI'!$A$5:$A$604,"<="&'02_SETARI'!$B$8),0) | D8: =IFERROR(IF(OR(B8="",C8="",C8="—"),"",B8-C8),"") | E8: Din fiecare 100 de lei încasați, atâția rămân ca profit brut.
A9: Clienți care au cumpărat | B9: =SUMPRODUCT(('11_CLIENTI'!$A$5:$A$124<>"")*(SUMIFS('10_VANZARI'!$E$5:$E$604,'10_VANZARI'!$B$5:$B$604,'11_CLIENTI'!$A$5:$A$124,'10_VANZARI'!$A$5:$A$604,">="&'02_SETARI'!$B$5,'10_VANZARI'!$A$5:$A$604,"<="&'02_SETARI'!$B$6)<>0)) | C9: =SUMPRODUCT(('11_CLIENTI'!$A$5:$A$124<>"")*(SUMIFS('10_VANZARI'!$E$5:$E$604,'10_VANZARI'!$B$5:$B$604,'11_CLIENTI'!$A$5:$A$124,'10_VANZARI'!$A$5:$A$604,">="&'02_SETARI'!$B$7,'10_VANZARI'!$A$5:$A$604,"<="&'02_SETARI'!$B$8)<>0)) | D9: =IFERROR(IF(OR(B9="",C9="",C9="—"),"",B9-C9),"") | E9: Câți clienți diferiți au cumpărat măcar o dată.
A10: Încasat mediu pe client | B10: =IFERROR(SUMIFS('10_VANZARI'!$E$5:$E$604,'10_VANZARI'!$A$5:$A$604,">="&'02_SETARI'!$B$5,'10_VANZARI'!$A$5:$A$604,"<="&'02_SETARI'!$B$6)/(SUMPRODUCT(('11_CLIENTI'!$A$5:$A$124<>"")*(SUMIFS('10_VANZARI'!$E$5:$E$604,'10_VANZARI'!$B$5:$B$604,'11_CLIENTI'!$A$5:$A$124,'10_VANZARI'!$A$5:$A$604,">="&'02_SETARI'!$B$5,'10_VANZARI'!$A$5:$A$604,"<="&'02_SETARI'!$B$6)<>0))),0) | C10: =IFERROR(SUMIFS('10_VANZARI'!$E$5:$E$604,'10_VANZARI'!$A$5:$A$604,">="&'02_SETARI'!$B$7,'10_VANZARI'!$A$5:$A$604,"<="&'02_SETARI'!$B$8)/(SUMPRODUCT(('11_CLIENTI'!$A$5:$A$124<>"")*(SUMIFS('10_VANZARI'!$E$5:$E$604,'10_VANZARI'!$B$5:$B$604,'11_CLIENTI'!$A$5:$A$124,'10_VANZARI'!$A$5:$A$604,">="&'02_SETARI'!$B$7,'10_VANZARI'!$A$5:$A$604,"<="&'02_SETARI'!$B$8)<>0))),0) | D10: =IFERROR(IF(OR(B10="",C10="",C10="—"),"",B10-C10),"") | E10: Dacă scade, clienții cumpără mai puțin, chiar dacă sunt la fel de mulți.
A11: Număr de facturi | B11: =SUMPRODUCT(('10_VANZARI'!$A$5:$A$604>='02_SETARI'!$B$5)*('10_VANZARI'!$A$5:$A$604<='02_SETARI'!$B$6)*('10_VANZARI'!$E$5:$E$604<>"")) | C11: =SUMPRODUCT(('10_VANZARI'!$A$5:$A$604>='02_SETARI'!$B$7)*('10_VANZARI'!$A$5:$A$604<='02_SETARI'!$B$8)*('10_VANZARI'!$E$5:$E$604<>"")) | D11: =IFERROR(IF(OR(B11="",C11="",C11="—"),"",B11-C11),"") | E11: Cât de des cumpără clienții.
A12: Valoare medie pe factură | B12: =IFERROR(SUMIFS('10_VANZARI'!$E$5:$E$604,'10_VANZARI'!$A$5:$A$604,">="&'02_SETARI'!$B$5,'10_VANZARI'!$A$5:$A$604,"<="&'02_SETARI'!$B$6)/(SUMPRODUCT(('10_VANZARI'!$A$5:$A$604>='02_SETARI'!$B$5)*('10_VANZARI'!$A$5:$A$604<='02_SETARI'!$B$6)*('10_VANZARI'!$E$5:$E$604<>""))),0) | C12: =IFERROR(SUMIFS('10_VANZARI'!$E$5:$E$604,'10_VANZARI'!$A$5:$A$604,">="&'02_SETARI'!$B$7,'10_VANZARI'!$A$5:$A$604,"<="&'02_SETARI'!$B$8)/(SUMPRODUCT(('10_VANZARI'!$A$5:$A$604>='02_SETARI'!$B$7)*('10_VANZARI'!$A$5:$A$604<='02_SETARI'!$B$8)*('10_VANZARI'!$E$5:$E$604<>""))),0) | D12: =IFERROR(IF(OR(B12="",C12="",C12="—"),"",B12-C12),"") | E12: Dacă scade, se vinde mai mărunt.
A13: Cel mai mare client | B13: =IFERROR(SUMPRODUCT(MAX(('11_CLIENTI'!$A$5:$A$124<>"")*SUMIFS('10_VANZARI'!$E$5:$E$604,'10_VANZARI'!$B$5:$B$604,'11_CLIENTI'!$A$5:$A$124,'10_VANZARI'!$A$5:$A$604,">="&'02_SETARI'!$B$5,'10_VANZARI'!$A$5:$A$604,"<="&'02_SETARI'!$B$6)))/SUMIFS('10_VANZARI'!$E$5:$E$604,'10_VANZARI'!$A$5:$A$604,">="&'02_SETARI'!$B$5,'10_VANZARI'!$A$5:$A$604,"<="&'02_SETARI'!$B$6),0) | C13: =IFERROR(SUMPRODUCT(MAX(('11_CLIENTI'!$A$5:$A$124<>"")*SUMIFS('10_VANZARI'!$E$5:$E$604,'10_VANZARI'!$B$5:$B$604,'11_CLIENTI'!$A$5:$A$124,'10_VANZARI'!$A$5:$A$604,">="&'02_SETARI'!$B$7,'10_VANZARI'!$A$5:$A$604,"<="&'02_SETARI'!$B$8)))/SUMIFS('10_VANZARI'!$E$5:$E$604,'10_VANZARI'!$A$5:$A$604,">="&'02_SETARI'!$B$7,'10_VANZARI'!$A$5:$A$604,"<="&'02_SETARI'!$B$8),0) | D13: =IFERROR(IF(OR(B13="",C13="",C13="—"),"",B13-C13),"") | E13: Cât din tot venitul vine de la un singur client. Peste 30%, e risc.
A14: Nota medie (NPS) | B14: =IFERROR(((SUMPRODUCT(('11_CLIENTI'!$A$5:$A$124<>"")*('11_CLIENTI'!$D$5:$D$124>=9)))-(SUMPRODUCT(('11_CLIENTI'!$A$5:$A$124<>"")*('11_CLIENTI'!$D$5:$D$124<>"")*('11_CLIENTI'!$D$5:$D$124<=6))))/(SUMPRODUCT(('11_CLIENTI'!$A$5:$A$124<>"")*('11_CLIENTI'!$D$5:$D$124<>"")))*100,"") | C14: — | D14: =IFERROR(IF(OR(B14="",C14="",C14="—"),"",B14-C14),"") | E14: De la −100 la +100. Peste 30 e bine, peste 50 e foarte bine.
A15: Clienți întrebați | B15: =SUMPRODUCT(('11_CLIENTI'!$A$5:$A$124<>"")*('11_CLIENTI'!$D$5:$D$124<>"")) | C15: — | D15: =IFERROR(IF(OR(B15="",C15="",C15="—"),"",B15-C15),"") | E15: Câți clienți ți-au dat o notă. Sub 10, cifra e doar orientativă.
A16: Cât își propunea să vândă | B16: ='02_SETARI'!$B$12 | C16: — | D16: =IFERROR(IF(OR(B16="",C16="",C16="—"),"",B16-C16),"") | E16: Din 02_SETARI.
A17: Cât din obiectiv a atins | B17: =IFERROR(SUMIFS('10_VANZARI'!$E$5:$E$604,'10_VANZARI'!$A$5:$A$604,">="&'02_SETARI'!$B$5,'10_VANZARI'!$A$5:$A$604,"<="&'02_SETARI'!$B$6)/'02_SETARI'!$B$12,"") | C17: — | D17: =IFERROR(IF(OR(B17="",C17="",C17="—"),"",B17-C17),"") | E17: Încasat împărțit la obiectiv.
A18: Cât mai lipsește | B18: =IF('02_SETARI'!$B$12=0,"",MAX(0,'02_SETARI'!$B$12-SUMIFS('10_VANZARI'!$E$5:$E$604,'10_VANZARI'!$A$5:$A$604,">="&'02_SETARI'!$B$5,'10_VANZARI'!$A$5:$A$604,"<="&'02_SETARI'!$B$6))) | C18: — | D18: =IFERROR(IF(OR(B18="",C18="",C18="—"),"",B18-C18),"") | E18: Aici începe planul de acțiune.
A20: CE SPUN CIFRELE
A21: =IF('20_REZULTATE'!$B$6=0,"Nu sunt vânzări în perioada aleasă. Verifică foaia 10_VANZARI și datele din 02_SETARI.","S-au încasat "&FIXED('20_REZULTATE'!$B$6,0)&" "&'02_SETARI'!$B$9&", din care "&FIXED('20_REZULTATE'!$B$7,0)&" profit brut (marjă "&FIXED(('20_REZULTATE'!$B$8)*100,1)&"%"&")."&IF('20_REZULTATE'!$C$6=0,"",IF('20_REZULTATE'!$B$6>='20_REZULTATE'!$C$6," Cu "&FIXED((('20_REZULTATE'!$B$6-'20_REZULTATE'!$C$6)/'20_REZULTATE'!$C$6)*100,1)&"%"&" mai mult decât în perioada comparată."," Cu "&FIXED((('20_REZULTATE'!$C$6-'20_REZULTATE'!$B$6)/'20_REZULTATE'!$C$6)*100,1)&"%"&" mai puțin decât în perioada comparată.")))
A22: =IF('20_REZULTATE'!$B$6=0,"—",IF('20_REZULTATE'!$B$8<'02_SETARI'!$B$16,"Marja e sub cât e normal în domeniu ("&FIXED(('02_SETARI'!$B$16)*100,1)&"%"&"). Fiecare procent recuperat la preț sau la cost înseamnă "&FIXED('20_REZULTATE'!$B$6*0.01,0)&" "&'02_SETARI'!$B$9&" în plus, fără să vinzi nimic nou.","Marja e peste pragul pe care l-ai pus ("&FIXED(('02_SETARI'!$B$16)*100,1)&"%"&"). Se poate crește volumul fără grijă."))
A23: =IF('20_REZULTATE'!$B$9=0,"—","Au cumpărat "&FIXED('20_REZULTATE'!$B$9,0)&" clienți, în medie "&FIXED('20_REZULTATE'!$B$10,0)&" "&'02_SETARI'!$B$9&" fiecare. Cel mai mare aduce "&FIXED(('20_REZULTATE'!$B$13)*100,1)&"%"&" din tot."&IF('20_REZULTATE'!$B$13>0.3," Asta e mult: dacă pleacă el, pleacă și profitul anului.",""))
A24: =IF('20_REZULTATE'!$B$15=0,"Niciun client nu are notă în 11_CLIENTI. Zece telefoane de câte două minute îți spun mai multe decât toate cifrele de mai sus.","Nota medie e "&FIXED('20_REZULTATE'!$B$14,0)&", din "&FIXED('20_REZULTATE'!$B$15,0)&" clienți întrebați."&IF('20_REZULTATE'!$B$15<10," Prea puțini ca să fie o concluzie — mai sună câțiva.",IF('20_REZULTATE'!$B$14<30," Sub 30 înseamnă că relația scârțâie undeva; citește ce au spus."," Peste 30 e o relație sănătoasă; cere-le recomandări.")))
A25: =IF('20_REZULTATE'!$B$16=0,"Nu ai pus un obiectiv în 02_SETARI. Fără el nu știi dacă "&FIXED('20_REZULTATE'!$B$6,0)&" e mult sau puțin.",IF('20_REZULTATE'!$B$18=0,"Obiectivul e atins. Următorul pas e să afli ce a funcționat, ca să repeți.","S-a atins "&FIXED(('20_REZULTATE'!$B$17)*100,1)&"%"&" din obiectiv. Mai lipsesc "&FIXED('20_REZULTATE'!$B$18,0)&" "&'02_SETARI'!$B$9&". Uită-te în 21_CE_SE_INTAMPLA: de obicei suma asta se găsește la 3-4 clienți."))
A26: =IF(AND(MAX(0,COUNTA('12_CONCURENTA'!$A$5:$A$14)-1)=0,SUMPRODUCT(('13_CE_CRED_OAMENII'!$D$6:$D$11<>"")*'13_CE_CRED_OAMENII'!$E$6:$E$11)=0),"Nu ai completat încă nimic despre concurență și reputație (foile 12 și 13). E cel mai ieftin context din tot fișierul: o oră pe internet, fără să întrebi pe nimeni.","Urmărim "&FIXED(MAX(0,COUNTA('12_CONCURENTA'!$A$5:$A$14)-1),0)&" concurenți. "&IF('12_CONCURENTA'!$F$5="","Firma nu are încă notă publică — verifică dacă are fișă Google Business. Un client nou o caută acolo înainte să sune.","Nota publică e "&FIXED('12_CONCURENTA'!$F$5,1)&" din 5"&IF(IFERROR(AVERAGE('12_CONCURENTA'!$F$6:$F$14),"")="",".",", față de "&FIXED(IFERROR(AVERAGE('12_CONCURENTA'!$F$6:$F$14),""),1)&" media concurenților"&IF('12_CONCURENTA'!$F$5>IFERROR(AVERAGE('12_CONCURENTA'!$F$6:$F$14),"")+0.2," — stăm mai bine decât ei.",IF('12_CONCURENTA'!$F$5<IFERROR(AVERAGE('12_CONCURENTA'!$F$6:$F$14),"")-0.2," — stăm mai slab; asta se rezolvă înainte de a crește volumul."," — la fel ca ei."))))&IF(SUMPRODUCT(('11_CLIENTI'!$A$5:$A$124<>"")*('11_CLIENTI'!$D$5:$D$124<>""))=0," NPS nu e măsurat încă: scorul de percepție din foaia 13 ține locul, dar nu îl înlocuiește.",""))

Sheet 21_CE_SE_INTAMPLA
A1: 21 — CE SE ÎNTÂMPLĂ CU FIECARE CLIENT
A2: Se completează singură din 10_VANZARI și 11_CLIENTI. Filtrează coloana „Ce se întâmplă” ca să vezi unde ai de lucru.
A4: Client | B4: Segment | C4: Încasat acum | D4: Încasat înainte | E4: Diferență | F4: Profit brut | G4: Marjă | H4: % din total | I4: Ultima comandă | J4: Zile de atunci | K4: Notă | L4: Ce se întâmplă | M4: Ce ai de făcut | N4: Cât poți recupera
A5: =IF('11_CLIENTI'!$A5="","",'11_CLIENTI'!$A5) | B5: =IF($A5="","",IFERROR(INDEX('11_CLIENTI'!$B$5:$B$124,MATCH($A5,'11_CLIENTI'!$A$5:$A$124,0)),"")) | C5: =IF($A5="","",SUMIFS('10_VANZARI'!$E$5:$E$604,'10_VANZARI'!$B$5:$B$604,$A5,'10_VANZARI'!$A$5:$A$604,">="&'02_SETARI'!$B$5,'10_VANZARI'!$A$5:$A$604,"<="&'02_SETARI'!$B$6)) | D5: =IF($A5="","",SUMIFS('10_VANZARI'!$E$5:$E$604,'10_VANZARI'!$B$5:$B$604,$A5,'10_VANZARI'!$A$5:$A$604,">="&'02_SETARI'!$B$7,'10_VANZARI'!$A$5:$A$604,"<="&'02_SETARI'!$B$8)) | E5: =IF($A5="","",IFERROR(IF($D5=0,"",($C5-$D5)/ABS($D5)),"")) | F5: =IF($A5="","",SUMIFS('10_VANZARI'!$G$5:$G$604,'10_VANZARI'!$B$5:$B$604,$A5,'10_VANZARI'!$A$5:$A$604,">="&'02_SETARI'!$B$5,'10_VANZARI'!$A$5:$A$604,"<="&'02_SETARI'!$B$6)) | G5: =IF($A5="","",IFERROR($F5/$C5,"")) | H5: =IF($A5="","",IFERROR($C5/SUMIFS('10_VANZARI'!$E$5:$E$604,'10_VANZARI'!$A$5:$A$604,">="&'02_SETARI'!$B$5,'10_VANZARI'!$A$5:$A$604,"<="&'02_SETARI'!$B$6),"")) | I5: =IF($A5="","",IFERROR(IF(SUMPRODUCT(MAX(('10_VANZARI'!$B$5:$B$604=$A5)*('10_VANZARI'!$E$5:$E$604<>"")*'10_VANZARI'!$A$5:$A$604))=0,"",SUMPRODUCT(MAX(('10_VANZARI'!$B$5:$B$604=$A5)*('10_VANZARI'!$E$5:$E$604<>"")*'10_VANZARI'!$A$5:$A$604))),"")) | J5: =IF(OR($A5="",$I5=""),"",'02_SETARI'!$B$19-$I5) | K5: =IF($A5="","",IFERROR(IF(INDEX('11_CLIENTI'!$D$5:$D$124,MATCH($A5,'11_CLIENTI'!$A$5:$A$124,0))="","",INDEX('11_CLIENTI'!$D$5:$D$124,MATCH($A5,'11_CLIENTI'!$A$5:$A$124,0))),"")) | L5: =IF($A5="","",IF(AND($K5<>"",$K5<='02_SETARI'!$B$18),"Nemulțumit",IF(AND($D5>0,$C5=0),"Nu mai cumpără",IF(AND($J5<>"",$J5>'02_SETARI'!$B$17,$D5>0),"Adormit",IF(AND($E5<>"",$E5<='02_SETARI'!$B$15),"A scăzut",IF(AND($C5>0,$G5<>"",$G5<'02_SETARI'!$B$16),"Marjă mică",IF(AND($E5<>"",$E5>=0.2),"În creștere",IF($C5=0,"Fără activitate","Merge bine")))))))) | M5: =IF($A5="","",IF($L5="Nu mai cumpără","Sună-l săptămâna asta și întreabă direct ce s-a schimbat. Nu trimite email.",IF($L5="Adormit","Sună-l cu un motiv concret: o ofertă, o noutate, o reamintire de sezon.",IF($L5="A scăzut","Întreabă-l dacă a împărțit comenzile cu altcineva. De obicei asta s-a întâmplat.",IF($L5="Nemulțumit","Citește ce a spus în 11_CLIENTI. Rezolvă exact acel lucru, apoi sună-l să-i confirmi. Știi deja cauza — nu mai e nevoie să o cauți.",IF($L5="Marjă mică","Verifică ce discount are și cât te costă să-l servești. Poate merită renegociat.",IF($L5="În creștere","Întreabă-l ce altceva i-ar mai trebui. Acum e momentul, nu peste șase luni.",IF($L5="Fără activitate","Client în listă, dar fără vânzări în perioadă. Verifică dacă mai e client.","Nimic urgent. Ține-l cald.")))))))) | N5: =IF($A5="","",IFERROR(IF($L5="Nu mai cumpără",$D5,IF($L5="Adormit",$D5,IF($L5="A scăzut",MAX(0,$D5-$C5),IF($L5="Marjă mică",MAX(0,$C5*('02_SETARI'!$B$16-$G5)),$C5*0.15)))),"")) | O5: =IF(OR($A5="",$C5="",N($C5)<=0),"",$C5+ROW()/1000000)
A6: =IF('11_CLIENTI'!$A6="","",'11_CLIENTI'!$A6) | B6: =IF($A6="","",IFERROR(INDEX('11_CLIENTI'!$B$5:$B$124,MATCH($A6,'11_CLIENTI'!$A$5:$A$124,0)),"")) | C6: =IF($A6="","",SUMIFS('10_VANZARI'!$E$5:$E$604,'10_VANZARI'!$B$5:$B$604,$A6,'10_VANZARI'!$A$5:$A$604,">="&'02_SETARI'!$B$5,'10_VANZARI'!$A$5:$A$604,"<="&'02_SETARI'!$B$6)) | D6: =IF($A6="","",SUMIFS('10_VANZARI'!$E$5:$E$604,'10_VANZARI'!$B$5:$B$604,$A6,'10_VANZARI'!$A$5:$A$604,">="&'02_SETARI'!$B$7,'10_VANZARI'!$A$5:$A$604,"<="&'02_SETARI'!$B$8)) | E6: =IF($A6="","",IFERROR(IF($D6=0,"",($C6-$D6)/ABS($D6)),"")) | F6: =IF($A6="","",SUMIFS('10_VANZARI'!$G$5:$G$604,'10_VANZARI'!$B$5:$B$604,$A6,'10_VANZARI'!$A$5:$A$604,">="&'02_SETARI'!$B$5,'10_VANZARI'!$A$5:$A$604,"<="&'02_SETARI'!$B$6)) | G6: =IF($A6="","",IFERROR($F6/$C6,"")) | H6: =IF($A6="","",IFERROR($C6/SUMIFS('10_VANZARI'!$E$5:$E$604,'10_VANZARI'!$A$5:$A$604,">="&'02_SETARI'!$B$5,'10_VANZARI'!$A$5:$A$604,"<="&'02_SETARI'!$B$6),"")) | I6: =IF($A6="","",IFERROR(IF(SUMPRODUCT(MAX(('10_VANZARI'!$B$5:$B$604=$A6)*('10_VANZARI'!$E$5:$E$604<>"")*'10_VANZARI'!$A$5:$A$604))=0,"",SUMPRODUCT(MAX(('10_VANZARI'!$B$5:$B$604=$A6)*('10_VANZARI'!$E$5:$E$604<>"")*'10_VANZARI'!$A$5:$A$604))),"")) | J6: =IF(OR($A6="",$I6=""),"",'02_SETARI'!$B$19-$I6) | K6: =IF($A6="","",IFERROR(IF(INDEX('11_CLIENTI'!$D$5:$D$124,MATCH($A6,'11_CLIENTI'!$A$5:$A$124,0))="","",INDEX('11_CLIENTI'!$D$5:$D$124,MATCH($A6,'11_CLIENTI'!$A$5:$A$124,0))),"")) | L6: =IF($A6="","",IF(AND($K6<>"",$K6<='02_SETARI'!$B$18),"Nemulțumit",IF(AND($D6>0,$C6=0),"Nu mai cumpără",IF(AND($J6<>"",$J6>'02_SETARI'!$B$17,$D6>0),"Adormit",IF(AND($E6<>"",$E6<='02_SETARI'!$B$15),"A scăzut",IF(AND($C6>0,$G6<>"",$G6<'02_SETARI'!$B$16),"Marjă mică",IF(AND($E6<>"",$E6>=0.2),"În creștere",IF($C6=0,"Fără activitate","Merge bine")))))))) | M6: =IF($A6="","",IF($L6="Nu mai cumpără","Sună-l săptămâna asta și întreabă direct ce s-a schimbat. Nu trimite email.",IF($L6="Adormit","Sună-l cu un motiv concret: o ofertă, o noutate, o reamintire de sezon.",IF($L6="A scăzut","Întreabă-l dacă a împărțit comenzile cu altcineva. De obicei asta s-a întâmplat.",IF($L6="Nemulțumit","Citește ce a spus în 11_CLIENTI. Rezolvă exact acel lucru, apoi sună-l să-i confirmi. Știi deja cauza — nu mai e nevoie să o cauți.",IF($L6="Marjă mică","Verifică ce discount are și cât te costă să-l servești. Poate merită renegociat.",IF($L6="În creștere","Întreabă-l ce altceva i-ar mai trebui. Acum e momentul, nu peste șase luni.",IF($L6="Fără activitate","Client în listă, dar fără vânzări în perioadă. Verifică dacă mai e client.","Nimic urgent. Ține-l cald.")))))))) | N6: =IF($A6="","",IFERROR(IF($L6="Nu mai cumpără",$D6,IF($L6="Adormit",$D6,IF($L6="A scăzut",MAX(0,$D6-$C6),IF($L6="Marjă mică",MAX(0,$C6*('02_SETARI'!$B$16-$G6)),$C6*0.15)))),"")) | O6: =IF(OR($A6="",$C6="",N($C6)<=0),"",$C6+ROW()/1000000)
A7: =IF('11_CLIENTI'!$A7="","",'11_CLIENTI'!$A7) | B7: =IF($A7="","",IFERROR(INDEX('11_CLIENTI'!$B$5:$B$124,MATCH($A7,'11_CLIENTI'!$A$5:$A$124,0)),"")) | C7: =IF($A7="","",SUMIFS('10_VANZARI'!$E$5:$E$604,'10_VANZARI'!$B$5:$B$604,$A7,'10_VANZARI'!$A$5:$A$604,">="&'02_SETARI'!$B$5,'10_VANZARI'!$A$5:$A$604,"<="&'02_SETARI'!$B$6)) | D7: =IF($A7="","",SUMIFS('10_VANZARI'!$E$5:$E$604,'10_VANZARI'!$B$5:$B$604,$A7,'10_VANZARI'!$A$5:$A$604,">="&'02_SETARI'!$B$7,'10_VANZARI'!$A$5:$A$604,"<="&'02_SETARI'!$B$8)) | E7: =IF($A7="","",IFERROR(IF($D7=0,"",($C7-$D7)/ABS($D7)),"")) | F7: =IF($A7="","",SUMIFS('10_VANZARI'!$G$5:$G$604,'10_VANZARI'!$B$5:$B$604,$A7,'10_VANZARI'!$A$5:$A$604,">="&'02_SETARI'!$B$5,'10_VANZARI'!$A$5:$A$604,"<="&'02_SETARI'!$B$6)) | G7: =IF($A7="","",IFERROR($F7/$C7,"")) | H7: =IF($A7="","",IFERROR($C7/SUMIFS('10_VANZARI'!$E$5:$E$604,'10_VANZARI'!$A$5:$A$604,">="&'02_SETARI'!$B$5,'10_VANZARI'!$A$5:$A$604,"<="&'02_SETARI'!$B$6),"")) | I7: =IF($A7="","",IFERROR(IF(SUMPRODUCT(MAX(('10_VANZARI'!$B$5:$B$604=$A7)*('10_VANZARI'!$E$5:$E$604<>"")*'10_VANZARI'!$A$5:$A$604))=0,"",SUMPRODUCT(MAX(('10_VANZARI'!$B$5:$B$604=$A7)*('10_VANZARI'!$E$5:$E$604<>"")*'10_VANZARI'!$A$5:$A$604))),"")) | J7: =IF(OR($A7="",$I7=""),"",'02_SETARI'!$B$19-$I7) | K7: =IF($A7="","",IFERROR(IF(INDEX('11_CLIENTI'!$D$5:$D$124,MATCH($A7,'11_CLIENTI'!$A$5:$A$124,0))="","",INDEX('11_CLIENTI'!$D$5:$D$124,MATCH($A7,'11_CLIENTI'!$A$5:$A$124,0))),"")) | L7: =IF($A7="","",IF(AND($K7<>"",$K7<='02_SETARI'!$B$18),"Nemulțumit",IF(AND($D7>0,$C7=0),"Nu mai cumpără",IF(AND($J7<>"",$J7>'02_SETARI'!$B$17,$D7>0),"Adormit",IF(AND($E7<>"",$E7<='02_SETARI'!$B$15),"A scăzut",IF(AND($C7>0,$G7<>"",$G7<'02_SETARI'!$B$16),"Marjă mică",IF(AND($E7<>"",$E7>=0.2),"În creștere",IF($C7=0,"Fără activitate","Merge bine")))))))) | M7: =IF($A7="","",IF($L7="Nu mai cumpără","Sună-l săptămâna asta și întreabă direct ce s-a schimbat. Nu trimite email.",IF($L7="Adormit","Sună-l cu un motiv concret: o ofertă, o noutate, o reamintire de sezon.",IF($L7="A scăzut","Întreabă-l dacă a împărțit comenzile cu altcineva. De obicei asta s-a întâmplat.",IF($L7="Nemulțumit","Citește ce a spus în 11_CLIENTI. Rezolvă exact acel lucru, apoi sună-l să-i confirmi. Știi deja cauza — nu mai e nevoie să o cauți.",IF($L7="Marjă mică","Verifică ce discount are și cât te costă să-l servești. Poate merită renegociat.",IF($L7="În creștere","Întreabă-l ce altceva i-ar mai trebui. Acum e momentul, nu peste șase luni.",IF($L7="Fără activitate","Client în listă, dar fără vânzări în perioadă. Verifică dacă mai e client.","Nimic urgent. Ține-l cald.")))))))) | N7: =IF($A7="","",IFERROR(IF($L7="Nu mai cumpără",$D7,IF($L7="Adormit",$D7,IF($L7="A scăzut",MAX(0,$D7-$C7),IF($L7="Marjă mică",MAX(0,$C7*('02_SETARI'!$B$16-$G7)),$C7*0.15)))),"")) | O7: =IF(OR($A7="",$C7="",N($C7)<=0),"",$C7+ROW()/1000000)
A8: =IF('11_CLIENTI'!$A8="","",'11_CLIENTI'!$A8) | B8: =IF($A8="","",IFERROR(INDEX('11_CLIENTI'!$B$5:$B$124,MATCH($A8,'11_CLIENTI'!$A$5:$A$124,0)),"")) | C8: =IF($A8="","",SUMIFS('10_VANZARI'!$E$5:$E$604,'10_VANZARI'!$B$5:$B$604,$A8,'10_VANZARI'!$A$5:$A$604,">="&'02_SETARI'!$B$5,'10_VANZARI'!$A$5:$A$604,"<="&'02_SETARI'!$B$6)) | D8: =IF($A8="","",SUMIFS('10_VANZARI'!$E$5:$E$604,'10_VANZARI'!$B$5:$B$604,$A8,'10_VANZARI'!$A$5:$A$604,">="&'02_SETARI'!$B$7,'10_VANZARI'!$A$5:$A$604,"<="&'02_SETARI'!$B$8)) | E8: =IF($A8="","",IFERROR(IF($D8=0,"",($C8-$D8)/ABS($D8)),"")) | F8: =IF($A8="","",SUMIFS('10_VANZARI'!$G$5:$G$604,'10_VANZARI'!$B$5:$B$604,$A8,'10_VANZARI'!$A$5:$A$604,">="&'02_SETARI'!$B$5,'10_VANZARI'!$A$5:$A$604,"<="&'02_SETARI'!$B$6)) | G8: =IF($A8="","",IFERROR($F8/$C8,"")) | H8: =IF($A8="","",IFERROR($C8/SUMIFS('10_VANZARI'!$E$5:$E$604,'10_VANZARI'!$A$5:$A$604,">="&'02_SETARI'!$B$5,'10_VANZARI'!$A$5:$A$604,"<="&'02_SETARI'!$B$6),"")) | I8: =IF($A8="","",IFERROR(IF(SUMPRODUCT(MAX(('10_VANZARI'!$B$5:$B$604=$A8)*('10_VANZARI'!$E$5:$E$604<>"")*'10_VANZARI'!$A$5:$A$604))=0,"",SUMPRODUCT(MAX(('10_VANZARI'!$B$5:$B$604=$A8)*('10_VANZARI'!$E$5:$E$604<>"")*'10_VANZARI'!$A$5:$A$604))),"")) | J8: =IF(OR($A8="",$I8=""),"",'02_SETARI'!$B$19-$I8) | K8: =IF($A8="","",IFERROR(IF(INDEX('11_CLIENTI'!$D$5:$D$124,MATCH($A8,'11_CLIENTI'!$A$5:$A$124,0))="","",INDEX('11_CLIENTI'!$D$5:$D$124,MATCH($A8,'11_CLIENTI'!$A$5:$A$124,0))),"")) | L8: =IF($A8="","",IF(AND($K8<>"",$K8<='02_SETARI'!$B$18),"Nemulțumit",IF(AND($D8>0,$C8=0),"Nu mai cumpără",IF(AND($J8<>"",$J8>'02_SETARI'!$B$17,$D8>0),"Adormit",IF(AND($E8<>"",$E8<='02_SETARI'!$B$15),"A scăzut",IF(AND($C8>0,$G8<>"",$G8<'02_SETARI'!$B$16),"Marjă mică",IF(AND($E8<>"",$E8>=0.2),"În creștere",IF($C8=0,"Fără activitate","Merge bine")))))))) | M8: =IF($A8="","",IF($L8="Nu mai cumpără","Sună-l săptămâna asta și întreabă direct ce s-a schimbat. Nu trimite email.",IF($L8="Adormit","Sună-l cu un motiv concret: o ofertă, o noutate, o reamintire de sezon.",IF($L8="A scăzut","Întreabă-l dacă a împărțit comenzile cu altcineva. De obicei asta s-a întâmplat.",IF($L8="Nemulțumit","Citește ce a spus în 11_CLIENTI. Rezolvă exact acel lucru, apoi sună-l să-i confirmi. Știi deja cauza — nu mai e nevoie să o cauți.",IF($L8="Marjă mică","Verifică ce discount are și cât te costă să-l servești. Poate merită renegociat.",IF($L8="În creștere","Întreabă-l ce altceva i-ar mai trebui. Acum e momentul, nu peste șase luni.",IF($L8="Fără activitate","Client în listă, dar fără vânzări în perioadă. Verifică dacă mai e client.","Nimic urgent. Ține-l cald.")))))))) | N8: =IF($A8="","",IFERROR(IF($L8="Nu mai cumpără",$D8,IF($L8="Adormit",$D8,IF($L8="A scăzut",MAX(0,$D8-$C8),IF($L8="Marjă mică",MAX(0,$C8*('02_SETARI'!$B$16-$G8)),$C8*0.15)))),"")) | O8: =IF(OR($A8="",$C8="",N($C8)<=0),"",$C8+ROW()/1000000)
A9: =IF('11_CLIENTI'!$A9="","",'11_CLIENTI'!$A9) | B9: =IF($A9="","",IFERROR(INDEX('11_CLIENTI'!$B$5:$B$124,MATCH($A9,'11_CLIENTI'!$A$5:$A$124,0)),"")) | C9: =IF($A9="","",SUMIFS('10_VANZARI'!$E$5:$E$604,'10_VANZARI'!$B$5:$B$604,$A9,'10_VANZARI'!$A$5:$A$604,">="&'02_SETARI'!$B$5,'10_VANZARI'!$A$5:$A$604,"<="&'02_SETARI'!$B$6)) | D9: =IF($A9="","",SUMIFS('10_VANZARI'!$E$5:$E$604,'10_VANZARI'!$B$5:$B$604,$A9,'10_VANZARI'!$A$5:$A$604,">="&'02_SETARI'!$B$7,'10_VANZARI'!$A$5:$A$604,"<="&'02_SETARI'!$B$8)) | E9: =IF($A9="","",IFERROR(IF($D9=0,"",($C9-$D9)/ABS($D9)),"")) | F9: =IF($A9="","",SUMIFS('10_VANZARI'!$G$5:$G$604,'10_VANZARI'!$B$5:$B$604,$A9,'10_VANZARI'!$A$5:$A$604,">="&'02_SETARI'!$B$5,'10_VANZARI'!$A$5:$A$604,"<="&'02_SETARI'!$B$6)) | G9: =IF($A9="","",IFERROR($F9/$C9,"")) | H9: =IF($A9="","",IFERROR($C9/SUMIFS('10_VANZARI'!$E$5:$E$604,'10_VANZARI'!$A$5:$A$604,">="&'02_SETARI'!$B$5,'10_VANZARI'!$A$5:$A$604,"<="&'02_SETARI'!$B$6),"")) | I9: =IF($A9="","",IFERROR(IF(SUMPRODUCT(MAX(('10_VANZARI'!$B$5:$B$604=$A9)*('10_VANZARI'!$E$5:$E$604<>"")*'10_VANZARI'!$A$5:$A$604))=0,"",SUMPRODUCT(MAX(('10_VANZARI'!$B$5:$B$604=$A9)*('10_VANZARI'!$E$5:$E$604<>"")*'10_VANZARI'!$A$5:$A$604))),"")) | J9: =IF(OR($A9="",$I9=""),"",'02_SETARI'!$B$19-$I9) | K9: =IF($A9="","",IFERROR(IF(INDEX('11_CLIENTI'!$D$5:$D$124,MATCH($A9,'11_CLIENTI'!$A$5:$A$124,0))="","",INDEX('11_CLIENTI'!$D$5:$D$124,MATCH($A9,'11_CLIENTI'!$A$5:$A$124,0))),"")) | L9: =IF($A9="","",IF(AND($K9<>"",$K9<='02_SETARI'!$B$18),"Nemulțumit",IF(AND($D9>0,$C9=0),"Nu mai cumpără",IF(AND($J9<>"",$J9>'02_SETARI'!$B$17,$D9>0),"Adormit",IF(AND($E9<>"",$E9<='02_SETARI'!$B$15),"A scăzut",IF(AND($C9>0,$G9<>"",$G9<'02_SETARI'!$B$16),"Marjă mică",IF(AND($E9<>"",$E9>=0.2),"În creștere",IF($C9=0,"Fără activitate","Merge bine")))))))) | M9: =IF($A9="","",IF($L9="Nu mai cumpără","Sună-l săptămâna asta și întreabă direct ce s-a schimbat. Nu trimite email.",IF($L9="Adormit","Sună-l cu un motiv concret: o ofertă, o noutate, o reamintire de sezon.",IF($L9="A scăzut","Întreabă-l dacă a împărțit comenzile cu altcineva. De obicei asta s-a întâmplat.",IF($L9="Nemulțumit","Citește ce a spus în 11_CLIENTI. Rezolvă exact acel lucru, apoi sună-l să-i confirmi. Știi deja cauza — nu mai e nevoie să o cauți.",IF($L9="Marjă mică","Verifică ce discount are și cât te costă să-l servești. Poate merită renegociat.",IF($L9="În creștere","Întreabă-l ce altceva i-ar mai trebui. Acum e momentul, nu peste șase luni.",IF($L9="Fără activitate","Client în listă, dar fără vânzări în perioadă. Verifică dacă mai e client.","Nimic urgent. Ține-l cald.")))))))) | N9: =IF($A9="","",IFERROR(IF($L9="Nu mai cumpără",$D9,IF($L9="Adormit",$D9,IF($L9="A scăzut",MAX(0,$D9-$C9),IF($L9="Marjă mică",MAX(0,$C9*('02_SETARI'!$B$16-$G9)),$C9*0.15)))),"")) | O9: =IF(OR($A9="",$C9="",N($C9)<=0),"",$C9+ROW()/1000000)
A10: =IF('11_CLIENTI'!$A10="","",'11_CLIENTI'!$A10) | B10: =IF($A10="","",IFERROR(INDEX('11_CLIENTI'!$B$5:$B$124,MATCH($A10,'11_CLIENTI'!$A$5:$A$124,0)),"")) | C10: =IF($A10="","",SUMIFS('10_VANZARI'!$E$5:$E$604,'10_VANZARI'!$B$5:$B$604,$A10,'10_VANZARI'!$A$5:$A$604,">="&'02_SETARI'!$B$5,'10_VANZARI'!$A$5:$A$604,"<="&'02_SETARI'!$B$6)) | D10: =IF($A10="","",SUMIFS('10_VANZARI'!$E$5:$E$604,'10_VANZARI'!$B$5:$B$604,$A10,'10_VANZARI'!$A$5:$A$604,">="&'02_SETARI'!$B$7,'10_VANZARI'!$A$5:$A$604,"<="&'02_SETARI'!$B$8)) | E10: =IF($A10="","",IFERROR(IF($D10=0,"",($C10-$D10)/ABS($D10)),"")) | F10: =IF($A10="","",SUMIFS('10_VANZARI'!$G$5:$G$604,'10_VANZARI'!$B$5:$B$604,$A10,'10_VANZARI'!$A$5:$A$604,">="&'02_SETARI'!$B$5,'10_VANZARI'!$A$5:$A$604,"<="&'02_SETARI'!$B$6)) | G10: =IF($A10="","",IFERROR($F10/$C10,"")) | H10: =IF($A10="","",IFERROR($C10/SUMIFS('10_VANZARI'!$E$5:$E$604,'10_VANZARI'!$A$5:$A$604,">="&'02_SETARI'!$B$5,'10_VANZARI'!$A$5:$A$604,"<="&'02_SETARI'!$B$6),"")) | I10: =IF($A10="","",IFERROR(IF(SUMPRODUCT(MAX(('10_VANZARI'!$B$5:$B$604=$A10)*('10_VANZARI'!$E$5:$E$604<>"")*'10_VANZARI'!$A$5:$A$604))=0,"",SUMPRODUCT(MAX(('10_VANZARI'!$B$5:$B$604=$A10)*('10_VANZARI'!$E$5:$E$604<>"")*'10_VANZARI'!$A$5:$A$604))),"")) | J10: =IF(OR($A10="",$I10=""),"",'02_SETARI'!$B$19-$I10) | K10: =IF($A10="","",IFERROR(IF(INDEX('11_CLIENTI'!$D$5:$D$124,MATCH($A10,'11_CLIENTI'!$A$5:$A$124,0))="","",INDEX('11_CLIENTI'!$D$5:$D$124,MATCH($A10,'11_CLIENTI'!$A$5:$A$124,0))),"")) | L10: =IF($A10="","",IF(AND($K10<>"",$K10<='02_SETARI'!$B$18),"Nemulțumit",IF(AND($D10>0,$C10=0),"Nu mai cumpără",IF(AND($J10<>"",$J10>'02_SETARI'!$B$17,$D10>0),"Adormit",IF(AND($E10<>"",$E10<='02_SETARI'!$B$15),"A scăzut",IF(AND($C10>0,$G10<>"",$G10<'02_SETARI'!$B$16),"Marjă mică",IF(AND($E10<>"",$E10>=0.2),"În creștere",IF($C10=0,"Fără activitate","Merge bine")))))))) | M10: =IF($A10="","",IF($L10="Nu mai cumpără","Sună-l săptămâna asta și întreabă direct ce s-a schimbat. Nu trimite email.",IF($L10="Adormit","Sună-l cu un motiv concret: o ofertă, o noutate, o reamintire de sezon.",IF($L10="A scăzut","Întreabă-l dacă a împărțit comenzile cu altcineva. De obicei asta s-a întâmplat.",IF($L10="Nemulțumit","Citește ce a spus în 11_CLIENTI. Rezolvă exact acel lucru, apoi sună-l să-i confirmi. Știi deja cauza — nu mai e nevoie să o cauți.",IF($L10="Marjă mică","Verifică ce discount are și cât te costă să-l servești. Poate merită renegociat.",IF($L10="În creștere","Întreabă-l ce altceva i-ar mai trebui. Acum e momentul, nu peste șase luni.",IF($L10="Fără activitate","Client în listă, dar fără vânzări în perioadă. Verifică dacă mai e client.","Nimic urgent. Ține-l cald.")))))))) | N10: =IF($A10="","",IFERROR(IF($L10="Nu mai cumpără",$D10,IF($L10="Adormit",$D10,IF($L10="A scăzut",MAX(0,$D10-$C10),IF($L10="Marjă mică",MAX(0,$C10*('02_SETARI'!$B$16-$G10)),$C10*0.15)))),"")) | O10: =IF(OR($A10="",$C10="",N($C10)<=0),"",$C10+ROW()/1000000)
A11: =IF('11_CLIENTI'!$A11="","",'11_CLIENTI'!$A11) | B11: =IF($A11="","",IFERROR(INDEX('11_CLIENTI'!$B$5:$B$124,MATCH($A11,'11_CLIENTI'!$A$5:$A$124,0)),"")) | C11: =IF($A11="","",SUMIFS('10_VANZARI'!$E$5:$E$604,'10_VANZARI'!$B$5:$B$604,$A11,'10_VANZARI'!$A$5:$A$604,">="&'02_SETARI'!$B$5,'10_VANZARI'!$A$5:$A$604,"<="&'02_SETARI'!$B$6)) | D11: =IF($A11="","",SUMIFS('10_VANZARI'!$E$5:$E$604,'10_VANZARI'!$B$5:$B$604,$A11,'10_VANZARI'!$A$5:$A$604,">="&'02_SETARI'!$B$7,'10_VANZARI'!$A$5:$A$604,"<="&'02_SETARI'!$B$8)) | E11: =IF($A11="","",IFERROR(IF($D11=0,"",($C11-$D11)/ABS($D11)),"")) | F11: =IF($A11="","",SUMIFS('10_VANZARI'!$G$5:$G$604,'10_VANZARI'!$B$5:$B$604,$A11,'10_VANZARI'!$A$5:$A$604,">="&'02_SETARI'!$B$5,'10_VANZARI'!$A$5:$A$604,"<="&'02_SETARI'!$B$6)) | G11: =IF($A11="","",IFERROR($F11/$C11,"")) | H11: =IF($A11="","",IFERROR($C11/SUMIFS('10_VANZARI'!$E$5:$E$604,'10_VANZARI'!$A$5:$A$604,">="&'02_SETARI'!$B$5,'10_VANZARI'!$A$5:$A$604,"<="&'02_SETARI'!$B$6),"")) | I11: =IF($A11="","",IFERROR(IF(SUMPRODUCT(MAX(('10_VANZARI'!$B$5:$B$604=$A11)*('10_VANZARI'!$E$5:$E$604<>"")*'10_VANZARI'!$A$5:$A$604))=0,"",SUMPRODUCT(MAX(('10_VANZARI'!$B$5:$B$604=$A11)*('10_VANZARI'!$E$5:$E$604<>"")*'10_VANZARI'!$A$5:$A$604))),"")) | J11: =IF(OR($A11="",$I11=""),"",'02_SETARI'!$B$19-$I11) | K11: =IF($A11="","",IFERROR(IF(INDEX('11_CLIENTI'!$D$5:$D$124,MATCH($A11,'11_CLIENTI'!$A$5:$A$124,0))="","",INDEX('11_CLIENTI'!$D$5:$D$124,MATCH($A11,'11_CLIENTI'!$A$5:$A$124,0))),"")) | L11: =IF($A11="","",IF(AND($K11<>"",$K11<='02_SETARI'!$B$18),"Nemulțumit",IF(AND($D11>0,$C11=0),"Nu mai cumpără",IF(AND($J11<>"",$J11>'02_SETARI'!$B$17,$D11>0),"Adormit",IF(AND($E11<>"",$E11<='02_SETARI'!$B$15),"A scăzut",IF(AND($C11>0,$G11<>"",$G11<'02_SETARI'!$B$16),"Marjă mică",IF(AND($E11<>"",$E11>=0.2),"În creștere",IF($C11=0,"Fără activitate","Merge bine")))))))) | M11: =IF($A11="","",IF($L11="Nu mai cumpără","Sună-l săptămâna asta și întreabă direct ce s-a schimbat. Nu trimite email.",IF($L11="Adormit","Sună-l cu un motiv concret: o ofertă, o noutate, o reamintire de sezon.",IF($L11="A scăzut","Întreabă-l dacă a împărțit comenzile cu altcineva. De obicei asta s-a întâmplat.",IF($L11="Nemulțumit","Citește ce a spus în 11_CLIENTI. Rezolvă exact acel lucru, apoi sună-l să-i confirmi. Știi deja cauza — nu mai e nevoie să o cauți.",IF($L11="Marjă mică","Verifică ce discount are și cât te costă să-l servești. Poate merită renegociat.",IF($L11="În creștere","Întreabă-l ce altceva i-ar mai trebui. Acum e momentul, nu peste șase luni.",IF($L11="Fără activitate","Client în listă, dar fără vânzări în perioadă. Verifică dacă mai e client.","Nimic urgent. Ține-l cald.")))))))) | N11: =IF($A11="","",IFERROR(IF($L11="Nu mai cumpără",$D11,IF($L11="Adormit",$D11,IF($L11="A scăzut",MAX(0,$D11-$C11),IF($L11="Marjă mică",MAX(0,$C11*('02_SETARI'!$B$16-$G11)),$C11*0.15)))),"")) | O11: =IF(OR($A11="",$C11="",N($C11)<=0),"",$C11+ROW()/1000000)
A12: =IF('11_CLIENTI'!$A12="","",'11_CLIENTI'!$A12) | B12: =IF($A12="","",IFERROR(INDEX('11_CLIENTI'!$B$5:$B$124,MATCH($A12,'11_CLIENTI'!$A$5:$A$124,0)),"")) | C12: =IF($A12="","",SUMIFS('10_VANZARI'!$E$5:$E$604,'10_VANZARI'!$B$5:$B$604,$A12,'10_VANZARI'!$A$5:$A$604,">="&'02_SETARI'!$B$5,'10_VANZARI'!$A$5:$A$604,"<="&'02_SETARI'!$B$6)) | D12: =IF($A12="","",SUMIFS('10_VANZARI'!$E$5:$E$604,'10_VANZARI'!$B$5:$B$604,$A12,'10_VANZARI'!$A$5:$A$604,">="&'02_SETARI'!$B$7,'10_VANZARI'!$A$5:$A$604,"<="&'02_SETARI'!$B$8)) | E12: =IF($A12="","",IFERROR(IF($D12=0,"",($C12-$D12)/ABS($D12)),"")) | F12: =IF($A12="","",SUMIFS('10_VANZARI'!$G$5:$G$604,'10_VANZARI'!$B$5:$B$604,$A12,'10_VANZARI'!$A$5:$A$604,">="&'02_SETARI'!$B$5,'10_VANZARI'!$A$5:$A$604,"<="&'02_SETARI'!$B$6)) | G12: =IF($A12="","",IFERROR($F12/$C12,"")) | H12: =IF($A12="","",IFERROR($C12/SUMIFS('10_VANZARI'!$E$5:$E$604,'10_VANZARI'!$A$5:$A$604,">="&'02_SETARI'!$B$5,'10_VANZARI'!$A$5:$A$604,"<="&'02_SETARI'!$B$6),"")) | I12: =IF($A12="","",IFERROR(IF(SUMPRODUCT(MAX(('10_VANZARI'!$B$5:$B$604=$A12)*('10_VANZARI'!$E$5:$E$604<>"")*'10_VANZARI'!$A$5:$A$604))=0,"",SUMPRODUCT(MAX(('10_VANZARI'!$B$5:$B$604=$A12)*('10_VANZARI'!$E$5:$E$604<>"")*'10_VANZARI'!$A$5:$A$604))),"")) | J12: =IF(OR($A12="",$I12=""),"",'02_SETARI'!$B$19-$I12) | K12: =IF($A12="","",IFERROR(IF(INDEX('11_CLIENTI'!$D$5:$D$124,MATCH($A12,'11_CLIENTI'!$A$5:$A$124,0))="","",INDEX('11_CLIENTI'!$D$5:$D$124,MATCH($A12,'11_CLIENTI'!$A$5:$A$124,0))),"")) | L12: =IF($A12="","",IF(AND($K12<>"",$K12<='02_SETARI'!$B$18),"Nemulțumit",IF(AND($D12>0,$C12=0),"Nu mai cumpără",IF(AND($J12<>"",$J12>'02_SETARI'!$B$17,$D12>0),"Adormit",IF(AND($E12<>"",$E12<='02_SETARI'!$B$15),"A scăzut",IF(AND($C12>0,$G12<>"",$G12<'02_SETARI'!$B$16),"Marjă mică",IF(AND($E12<>"",$E12>=0.2),"În creștere",IF($C12=0,"Fără activitate","Merge bine")))))))) | M12: =IF($A12="","",IF($L12="Nu mai cumpără","Sună-l săptămâna asta și întreabă direct ce s-a schimbat. Nu trimite email.",IF($L12="Adormit","Sună-l cu un motiv concret: o ofertă, o noutate, o reamintire de sezon.",IF($L12="A scăzut","Întreabă-l dacă a împărțit comenzile cu altcineva. De obicei asta s-a întâmplat.",IF($L12="Nemulțumit","Citește ce a spus în 11_CLIENTI. Rezolvă exact acel lucru, apoi sună-l să-i confirmi. Știi deja cauza — nu mai e nevoie să o cauți.",IF($L12="Marjă mică","Verifică ce discount are și cât te costă să-l servești. Poate merită renegociat.",IF($L12="În creștere","Întreabă-l ce altceva i-ar mai trebui. Acum e momentul, nu peste șase luni.",IF($L12="Fără activitate","Client în listă, dar fără vânzări în perioadă. Verifică dacă mai e client.","Nimic urgent. Ține-l cald.")))))))) | N12: =IF($A12="","",IFERROR(IF($L12="Nu mai cumpără",$D12,IF($L12="Adormit",$D12,IF($L12="A scăzut",MAX(0,$D12-$C12),IF($L12="Marjă mică",MAX(0,$C12*('02_SETARI'!$B$16-$G12)),$C12*0.15)))),"")) | O12: =IF(OR($A12="",$C12="",N($C12)<=0),"",$C12+ROW()/1000000)
A13: =IF('11_CLIENTI'!$A13="","",'11_CLIENTI'!$A13) | B13: =IF($A13="","",IFERROR(INDEX('11_CLIENTI'!$B$5:$B$124,MATCH($A13,'11_CLIENTI'!$A$5:$A$124,0)),"")) | C13: =IF($A13="","",SUMIFS('10_VANZARI'!$E$5:$E$604,'10_VANZARI'!$B$5:$B$604,$A13,'10_VANZARI'!$A$5:$A$604,">="&'02_SETARI'!$B$5,'10_VANZARI'!$A$5:$A$604,"<="&'02_SETARI'!$B$6)) | D13: =IF($A13="","",SUMIFS('10_VANZARI'!$E$5:$E$604,'10_VANZARI'!$B$5:$B$604,$A13,'10_VANZARI'!$A$5:$A$604,">="&'02_SETARI'!$B$7,'10_VANZARI'!$A$5:$A$604,"<="&'02_SETARI'!$B$8)) | E13: =IF($A13="","",IFERROR(IF($D13=0,"",($C13-$D13)/ABS($D13)),"")) | F13: =IF($A13="","",SUMIFS('10_VANZARI'!$G$5:$G$604,'10_VANZARI'!$B$5:$B$604,$A13,'10_VANZARI'!$A$5:$A$604,">="&'02_SETARI'!$B$5,'10_VANZARI'!$A$5:$A$604,"<="&'02_SETARI'!$B$6)) | G13: =IF($A13="","",IFERROR($F13/$C13,"")) | H13: =IF($A13="","",IFERROR($C13/SUMIFS('10_VANZARI'!$E$5:$E$604,'10_VANZARI'!$A$5:$A$604,">="&'02_SETARI'!$B$5,'10_VANZARI'!$A$5:$A$604,"<="&'02_SETARI'!$B$6),"")) | I13: =IF($A13="","",IFERROR(IF(SUMPRODUCT(MAX(('10_VANZARI'!$B$5:$B$604=$A13)*('10_VANZARI'!$E$5:$E$604<>"")*'10_VANZARI'!$A$5:$A$604))=0,"",SUMPRODUCT(MAX(('10_VANZARI'!$B$5:$B$604=$A13)*('10_VANZARI'!$E$5:$E$604<>"")*'10_VANZARI'!$A$5:$A$604))),"")) | J13: =IF(OR($A13="",$I13=""),"",'02_SETARI'!$B$19-$I13) | K13: =IF($A13="","",IFERROR(IF(INDEX('11_CLIENTI'!$D$5:$D$124,MATCH($A13,'11_CLIENTI'!$A$5:$A$124,0))="","",INDEX('11_CLIENTI'!$D$5:$D$124,MATCH($A13,'11_CLIENTI'!$A$5:$A$124,0))),"")) | L13: =IF($A13="","",IF(AND($K13<>"",$K13<='02_SETARI'!$B$18),"Nemulțumit",IF(AND($D13>0,$C13=0),"Nu mai cumpără",IF(AND($J13<>"",$J13>'02_SETARI'!$B$17,$D13>0),"Adormit",IF(AND($E13<>"",$E13<='02_SETARI'!$B$15),"A scăzut",IF(AND($C13>0,$G13<>"",$G13<'02_SETARI'!$B$16),"Marjă mică",IF(AND($E13<>"",$E13>=0.2),"În creștere",IF($C13=0,"Fără activitate","Merge bine")))))))) | M13: =IF($A13="","",IF($L13="Nu mai cumpără","Sună-l săptămâna asta și întreabă direct ce s-a schimbat. Nu trimite email.",IF($L13="Adormit","Sună-l cu un motiv concret: o ofertă, o noutate, o reamintire de sezon.",IF($L13="A scăzut","Întreabă-l dacă a împărțit comenzile cu altcineva. De obicei asta s-a întâmplat.",IF($L13="Nemulțumit","Citește ce a spus în 11_CLIENTI. Rezolvă exact acel lucru, apoi sună-l să-i confirmi. Știi deja cauza — nu mai e nevoie să o cauți.",IF($L13="Marjă mică","Verifică ce discount are și cât te costă să-l servești. Poate merită renegociat.",IF($L13="În creștere","Întreabă-l ce altceva i-ar mai trebui. Acum e momentul, nu peste șase luni.",IF($L13="Fără activitate","Client în listă, dar fără vânzări în perioadă. Verifică dacă mai e client.","Nimic urgent. Ține-l cald.")))))))) | N13: =IF($A13="","",IFERROR(IF($L13="Nu mai cumpără",$D13,IF($L13="Adormit",$D13,IF($L13="A scăzut",MAX(0,$D13-$C13),IF($L13="Marjă mică",MAX(0,$C13*('02_SETARI'!$B$16-$G13)),$C13*0.15)))),"")) | O13: =IF(OR($A13="",$C13="",N($C13)<=0),"",$C13+ROW()/1000000)
