Workbook

Sheet 00_GHID
A1: EQUIL GROWTH INTELLIGENCE — v0.2
A2: Pachet de colectare a datelor + motor de KPI, semnale și oportunități. Completează doar celulele galbene.
A4: LA CE FOLOSEȘTE | B4: Transformă datele brute ale unei firme în KPI, semnale de risc și oportunități de creștere prioritizate, plus un raport gata de prezentat.
A5: CUM SE FOLOSEȘTE
A6: Pas 1 — Profil | B6: Completează 01_FIRMA în discuția de kickoff. Durează 20 de minute și îți dă contextul pentru tot restul.
A7: Pas 2 — Oameni | B7: Completează 02_CONTACTE: cine, din firmă, deține fiecare set de date. Fără asta, colectarea se blochează.
A8: Pas 3 — Cerere date | B8: Trimite 03_CHECKLIST_DATE. Fiecare rând spune ce câmp ceri, din ce sistem se scoate, cine îl poate da și ce deblochează. Filtrează pe „Obligatoriu” pentru setul minim viabil.
A9: Pas 4 — Parametri | B9: Setează în 09_PARAMETRI perioada analizată, perioada de comparație și pragurile. Toate calculele se recalculează automat.
A10: Pas 5 — Import date | B10: Lipește datele în 10_CLIENTI, 11_PRODUSE, 12_OAMENI, 13_VANZARI, 14_TINTE, 15_NPS. Coloanele gri au formule — nu le suprascrie.
A11: Pas 6 — Citește | B11: Verifică 20_KPI, apoi 21/22/23 pentru semnale pe clienți, produse și oameni.
A12: Pas 7 — Prioritizează | B12: Preia semnalele în 30_OPORTUNITATI. Scor = Impact × Probabilitate × Ușurință. Prioritatea se calculează din pragurile din 09_PARAMETRI.
A13: Pas 8 — Prezintă | B13: 40_RAPORT este structura pentru clientul final; se completează singur din foile anterioare.
A15: COD DE CULORI
A16: Galben | B16: Celulă de completat (de tine sau de client).
A17: Gri | B17: Celulă calculată automat. Nu se scrie în ea.
A18: Verde-închis | B18: Antet de tabel.
A20: SETUL MINIM VIABIL | B20: Cu doar 3 lucruri se poate produce un prim raport: (1) vânzări pe 24 de luni cu client, produs, venit net și cost; (2) nomenclatorul de clienți; (3) ținta de venit pe perioadă. Restul îmbogățește analiza.
A21: ISTORIC RECOMANDAT | B21: Minim 13 luni (pentru comparație an/an), ideal 24-36 de luni.
A23: REGULI DE IGIENĂ A DATELOR
A24: Un ID = o entitate | B24: Fiecare client și produs are un singur ID, constant în toate foile.
A25: Valori fără TVA | B25: Veniturile și costurile se dau nete, în aceeași monedă.
A26: Stornări | B26: Se trec ca linii separate, cu valori negative.
A27: Fără celule „mixte” | B27: Nu combina text și cifre în aceeași celulă (ex. „12.000 lei” → 12000).
A28: Date personale | B28: Pentru NPS și oameni, folosește inițiale sau ID-uri dacă firma nu a agreat nominalizarea. Semnează NDA înainte de a primi datele.
A30: UN FIȘIER PENTRU FIECARE FIRMĂ
A31: Regula | B31: Nu amesteca două firme în același fișier. Păstrezi acest fișier ca șablon nemodificat și faci o copie pentru fiecare client.
A32: Cod de firmă | B32: Fiecare firmă primește un cod în 01_FIRMA (EQ-0001, EQ-0002…). Codul rămâne același pentru totdeauna, chiar dacă firma își schimbă numele.
A33: Nume fișier | B33: EQUIL_<cod>_<NumeFirma>_<AAAA-LL>.xlsx — ex. EQUIL_EQ-0001_AlfaSRL_2026-06.xlsx. Perioada din nume îți spune din ce rulaj e fișierul.
A34: Refolosire lunară | B34: Pentru luna următoare la aceeași firmă: copiază fișierul, schimbă perioada în 09_PARAMETRI și adaugă noile linii de vânzări. Nu ștergi istoricul.
A35: Șablonul | B35: Ține o copie curată, fără date, într-un folder separat („_SABLON”). Din ea pleacă fiecare firmă nouă.
A37: CÂT DUREAZĂ (estimat, prima rulare)
A38: 01_FIRMA | B38: 20-30 min, în discuția de kickoff, împreună cu clientul.
A39: 02_CONTACTE | B39: 10-15 min, tot la kickoff. Cea mai bună investiție de timp din tot procesul.
A40: 03_CHECKLIST_DATE | B40: 15 min să-l trimiți și să-l explici. Apoi 3-10 zile lucrătoare de așteptare, cu 2-3 follow-up-uri scurte.
A41: Import date | B41: 30-60 min dacă exporturile sunt curate. 2-4 ore dacă trebuie curățate manual (denumiri inconsecvente, valori cu text, ID-uri lipsă).
A42: 09_PARAMETRI | B42: 5 min. Pragurile se ajustează pe industrie.
A43: Citit 20-23 | B43: 30-45 min de citit semnalele și de verificat dacă au sens.
A44: 30_OPORTUNITATI | B44: 45-60 min: transformi semnalele în oportunități, estimezi impactul, pui responsabili.
A45: 40_RAPORT + grafice | B45: 30-45 min: concluziile automate îți dau schița, tu scrii varianta pentru client.
A46: TOTAL munca ta | B46: aprox. 4-6 ore de lucru efectiv, întinse pe 1-2 săptămâni calendaristice (așteptarea datelor domină).
...

Sheet 01_FIRMA
A1: 01 — PROFILUL FIRMEI
A2: Se completează la kickoff, împreună cu clientul. Câmpurile galbene sunt de completat.
A4: IDENTIFICARE
A5: Cod client EQUIL | C5: ID-ul intern al firmei în portofoliul tău. Format recomandat: EQ-0001, EQ-0002…
A6: Denumire legală | C6: Exact ca la Registrul Comerțului.
A7: CUI / Cod fiscal
A8: Nr. Registrul Comerțului
A9: Site web
A10: Industrie / CAEN principal | C10: Determină benchmark-urile folosite.
A11: Sub-industrie / nișă
A12: An înființare
A13: Model de business | C13: B2B / B2C / Mix / Marketplace.
A14: Piețe / regiuni acoperite
A15: DIMENSIUNE
A16: Număr total angajați | C16: Total, nu doar vânzări.
A17: Din care în vânzări
A18: Cifra de afaceri — ultimul an încheiat | C18: Fără TVA.
A19: Profit brut — ultimul an încheiat
A20: Număr clienți activi | C20: Clienți cu cel puțin o achiziție în ultimele 12 luni.
A21: Număr produse / SKU active
A22: Sezonalitate | C22: Lunile de vârf și lunile slabe.
A23: SISTEME ȘI DATE
A24: ERP / sistem de facturare | C24: Ex. SAGA, WinMentor, SAP, Oracle NetSuite, Smartbill.
A25: CRM | C25: Ex. HubSpot, Pipedrive, Salesforce, Excel.
A26: Instrument de raportare | C26: Ex. Excel, Power BI, Looker, nimic.
A27: Se pot exporta datele în Excel/CSV? | C27: Da / Nu / Parțial — și cine face exportul.
A28: Istoric disponibil (luni) | C28: Câte luni de date se pot scoate din sisteme.
A29: Se măsoară deja NPS? | C29: Da / Nu. Dacă da, de când și cum.
A30: OBIECTIVE ȘI CONTEXT
A31: Obiectivul principal pe 12 luni | C31: Exprimat în cifre, dacă se poate.
A32: Cele 3 provocări majore
A33: Ce au încercat deja și nu a mers
A34: Cine ia decizia finală | C34: Numele și rolul decidentului.
A35: MANDAT EQUIL
A36: Perioada analizată | C36: Trebuie să coincidă cu 09_PARAMETRI.
A37: Moneda de raportare
A38: Consultant EQUIL responsabil
A39: Data kickoff
A40: Data livrării raportului
A41: NDA semnat | C41: Da / Nu / Data. NDA = acord de confidențialitate; vezi 04_DICTIONAR.
...

Sheet 02_CONTACTE
A1: 02 — CINE FURNIZEAZĂ DATELE (data owners)
A2: Sfat: nu cere „toate datele”. Cere de la fiecare om exact setul din 03_CHECKLIST_DATE care îi este atribuit, cu un termen concret.
A4: Cod contact Contact_ID | B4: Rol în firmă Rol_in_firma | C4: Nume și prenume Nume | D4: Funcția exactă Functie_exacta | E4: Email Email | F4: Telefon Telefon | G4: Ce date poate furniza Seturi_de_date_detinute | H4: Sisteme la care are acces Sisteme_la_care_are_acces | I4: Poate aproba transmiterea? (Da/Nu) Decident | J4: Canal preferat de contact Canal_preferat | K4: Disponibilitate Disponibilitate | L4: Data solicitării Data_solicitarii | M4: Termen agreat Termen_agreat | N4: Status Status | O4: Observații Observatii
A5: CT01 | B5: CEO / Administrator | G5: Obiective, context strategic, aprobarea transmiterii datelor | H5: — | I5: Da | J5: Întâlnire | N5: Nesolicitat | O5: Decide ce date pot ieși din firmă.
A6: CT02 | B6: CFO / Contabilitate | G6: Venituri, costuri (COGS), balanță, ținte/buget, termene de plată | H6: ERP, contabilitate | I6: Da | J6: Email | N6: Nesolicitat | O6: Sursa principală pentru profit brut și marjă.
A7: CT03 | B7: Director Vânzări | G7: Clienți, segmente, canale, ținte pe oameni, context comercial | H7: CRM | I7: Da | J7: Telefon | N7: Nesolicitat | O7: Validează interpretarea semnalelor.
A8: CT04 | B8: Sales Ops / CRM | G8: Export CRM: clienți, responsabili de cont, pipeline, activitate | H8: CRM | I8: Nu | J8: Email | N8: Nesolicitat | O8: De obicei cel care face efectiv exportul.
A9: CT05 | B9: IT / ERP | G9: Export brut din ERP: facturi, nomenclator produse, clienți | H9: ERP | I9: Nu | J9: Email | N9: Nesolicitat | O9: Cere formatul CSV/XLSX, nu PDF.
A10: CT06 | B10: Marketing | G10: NPS, campanii, lansări de produs, lead-uri | H10: Survey, web | I10: Nu | J10: Email | N10: Nesolicitat | O10: Deține de obicei instrumentul de chestionar.
A11: CT07 | B11: HR / Resurse Umane | G11: Structura echipei, FTE, intrări/ieșiri, cost cu personalul | H11: HR / salarizare | I11: Da | J11: Email | N11: Nesolicitat | O11: Atenție la GDPR: cere agregat sau anonimizat.
A12: CT08 | B12: Customer Service | G12: Reclamații, motive de nemulțumire, follow-up detractori | H12: Ticketing | I12: Nu | J12: Telefon | N12: Nesolicitat | O12: Sursa cea mai bogată de cauze calitative.
A13: CT09 | B13: Operațiuni / Logistică | G13: Livrări, stocuri, termene, capacitate | H13: ERP / WMS | I13: Nu | J13: Email | N13: Nesolicitat | O13: Relevant când NPS scade din cauza livrării.

Sheet 03_CHECKLIST_DATE
A1: 03 — CE DATE CER ȘI DE LA CINE
A2: Lista completă a câmpurilor. Filtrează pe Obligatoriu = „Obligatoriu” pentru setul minim viabil. Coloana „Persoana” se leagă de numele din 02_CONTACTE.
A4: ID | B4: Set de date | C4: Foaie destinație | D4: Câmp (tehnic) | E4: Denumire RO | F4: Ce înseamnă / cum se completează | G4: Obligatoriu | H4: Format / unitate | I4: Exemplu | J4: Sursă tipică | K4: Rol furnizor | L4: Persoana (nume) | M4: Ce deblochează | N4: Status | O4: Data primirii | P4: Observații | R4: PROGRES COLECTARE
A5: D001 | B5: Profil firmă | C5: 01_FIRMA | E5: Profil complet firmă | F5: Se completează în discuția de kickoff: identificare, dimensiune, sisteme, obiective. | G5: Obligatoriu | H5: Text | I5: vezi 01_FIRMA | J5: Interviu / Workshop | K5: CEO / Administrator | M5: Context pentru toate interpretările | N5: Nesolicitat | R5: Total câmpuri cerute | S5: =COUNTA($A$5:$A$70)
A6: D002 | B6: Documente / context | C6: — | E6: NDA semnat | F6: Acord de confidențialitate semnat înainte de transmiterea oricăror date. | G6: Obligatoriu | H6: PDF | I6: NDA_2026.pdf | J6: Interviu / Workshop | K6: CEO / Administrator | M6: Permite transmiterea legală a datelor | N6: Nesolicitat | R6: Din care obligatorii | S6: =COUNTIF($G$5:$G$70,"Obligatoriu")
A7: D003 | B7: Documente / context | C7: — | E7: Organigramă echipă comercială | F7: Structura echipei: cine cui raportează, cine acoperă ce zonă sau segment. | G7: Recomandat | H7: PDF / imagine | I7: organigrama.pdf | J7: HR / State de plată | K7: HR / Resurse Umane | M7: Interpretarea corectă a analizei pe oameni | N7: Nesolicitat | R7: Primite sau validate | S7: =COUNTIF($N$5:$N$70,"Primit")+COUNTIF($N$5:$N$70,"Validat")
A8: D004 | B8: Documente / context | C8: — | E8: Listă de prețuri și politică de discount | F8: Prețurile de listă și regulile de discount pe segment sau volum. | G8: Recomandat | H8: XLSX | I8: pricelist_2026.xlsx | J8: Excel intern | K8: Director Vânzări | M8: Analiza erodării de preț și a marjei | N8: Nesolicitat | R8: Obligatorii încă lipsă | S8: =COUNTIFS($G$5:$G$70,"Obligatoriu",$N$5:$N$70,"<>Primit",$N$5:$N$70,"<>Validat")
A9: D005 | B9: Financiar | C9: — | E9: Balanță / P&L ultimele 24 de luni | F9: Pentru validarea veniturilor și a costurilor față de contabilitate. | G9: Recomandat | H9: XLSX / PDF | I9: balanta_2025.xlsx | J9: Balanță / Contabilitate | K9: CFO / Contabilitate | M9: Verificarea consistenței cifrelor | N9: Nesolicitat | R9: Blocate | S9: =COUNTIF($N$5:$N$70,"Blocat")
A10: D006 | B10: Financiar | C10: — | E10: Cheltuieli fixe lunare (agregat) | F10: Costuri indirecte lunare, agregat. Nu e nevoie de detaliu pe furnizor. | G10: Opțional | H10: Valoare / lună | I10: 180000 | J10: Balanță / Contabilitate | K10: CFO / Contabilitate | M10: Prag de rentabilitate, impact real al oportunităților | N10: Nesolicitat | R10: % completare | S10: =IFERROR((S7)/(S5),0)
A11: D007 | B11: Documente / context | C11: — | E11: Acces la export ERP (recurent) | F11: Cine face exportul lunar și în ce format, pentru actualizări periodice. | G11: Recomandat | H11: Proces | I11: export lunar CSV | J11: ERP / Facturare | K11: IT / ERP | M11: Repetabilitatea raportului, nu doar o dată | N11: Nesolicitat | R11: % completare obligatorii | S11: =IFERROR(1-(S8)/(S6),0)
A12: D008 | B12: Vânzări | C12: 13_VANZARI | D12: Doc_Date | E12: Data document | F12: Data facturii sau a lunii de raportare. O linie = o combinație client × produs × perioadă. | G12: Obligatoriu | H12: yyyy-mm-dd | I12: 2026-01-31 | J12: ERP / Facturare | K12: CFO / Contabilitate | M12: Toate KPI-urile și trendurile | N12: Nesolicitat
A13: D009 | B13: Vânzări | C13: 13_VANZARI | D13: Doc_Type | E13: Tip document | F13: Factură / Storno / Avans. Stornările se trec cu valori negative. | G13: Recomandat | H13: Text | I13: Factură | J13: ERP / Facturare | K13: CFO / Contabilitate | M13: Corectitudinea veniturilor | N13: Nesolicitat
A14: D010 | B14: Vânzări | C14: 13_VANZARI | D14: Customer_ID | E14: ID client | F14: Trebuie să existe în 10_CLIENTI. | G14: Obligatoriu | H14: Text | I14: C001 | J14: ERP / Facturare | K14: IT / ERP | M14: Analiză client, concentrare | N14: Nesolicitat
A15: D011 | B15: Vânzări | C15: 13_VANZARI | D15: Product_ID | E15: ID produs | F15: Trebuie să existe în 11_PRODUSE. | G15: Obligatoriu | H15: Text | I15: P001 | J15: ERP / Facturare | K15: IT / ERP | M15: Analiză produs, cross-sell | N15: Nesolicitat
A16: D012 | B16: Vânzări | C16: 13_VANZARI | D16: Person_ID | E16: ID persoană vânzări | F16: Cine a făcut vânzarea; trebuie să existe în 12_OAMENI. | G16: Recomandat | H16: Text | I16: S001 | J16: CRM | K16: Sales Ops / CRM | M16: Productivitate pe om | N16: Nesolicitat
A17: D013 | B17: Vânzări | C17: 13_VANZARI | D17: Units | E17: Cantitate | F17: Număr de unități / ore / licențe. | G17: Recomandat | H17: #,##0.00 | I17: 100 | J17: ERP / Facturare | K17: IT / ERP | M17: Preț mediu, volum vs. preț | N17: Nesolicitat
A18: D014 | B18: Vânzări | C18: 13_VANZARI | D18: Revenue_Net | E18: Venit net | F18: Venit fără TVA, după discount. | G18: Obligatoriu | H18: #,##0 | I18: 10000 | J18: ERP / Facturare | K18: CFO / Contabilitate | M18: Venit, creștere, țintă | N18: Nesolicitat
A19: D015 | B19: Vânzări | C19: 13_VANZARI | D19: Discount_Value | E19: Valoare discount | F19: Discountul acordat, în valoare absolută. | G19: Opțional | H19: #,##0 | I19: 800 | J19: ERP / Facturare | K19: CFO / Contabilitate | M19: Erodare preț, marjă | N19: Nesolicitat
A20: D016 | B20: Vânzări | C20: 13_VANZARI | D20: COGS | E20: Cost direct (COGS) | F20: Costul direct aferent vânzării. | G20: Obligatoriu | H20: #,##0 | I20: 7500 | J20: Balanță / Contabilitate | K20: CFO / Contabilitate | M20: Profit brut, marjă | N20: Nesolicitat
A21: D017 | B21: Vânzări | C21: 13_VANZARI | D21: Currency | E21: Monedă | F21: Moneda documentului. Ideal toate liniile în aceeași monedă. | G21: Recomandat | H21: Text | I21: RON | J21: ERP / Facturare | K21: CFO / Contabilitate | M21: Consistența raportării | N21: Nesolicitat
A22: D018 | B22: Vânzări | C22: 13_VANZARI | D22: Notes | E22: Observații | F22: Context pe linie, dacă e nevoie. | G22: Opțional | H22: Text | J22: Interviu / Workshop | K22: Director Vânzări | M22: Context | N22: Nesolicitat
A23: D019 | B23: Clienți | C23: 10_CLIENTI | D23: Customer_ID | E23: ID client | F23: Cod unic de client, exact cum apare în ERP/CRM. Se folosește în foaia de vânzări. | G23: Obligatoriu | H23: Text | I23: C001 | J23: ERP / Facturare | K23: IT / ERP | M23: Toate analizele pe client | N23: Nesolicitat
A24: D020 | B24: Clienți | C24: 10_CLIENTI | D24: Customer_Name | E24: Denumire client | F24: Denumirea comercială a clientului. | G24: Obligatoriu | H24: Text | I24: Alfa Distribution SRL | J24: ERP / Facturare | K24: Director Vânzări | M24: Raport client, top clienți | N24: Nesolicitat
A25: D021 | B25: Clienți | C25: 10_CLIENTI | D25: Segment | E25: Segment | F25: Segmentul de client (ex. Key Account, Mid, Small, Online). | G25: Recomandat | H25: Text | I25: Key Account | J25: CRM | K25: Director Vânzări | M25: Analiză pe segmente | N25: Nesolicitat
A26: D022 | B26: Clienți | C26: 10_CLIENTI | D26: Channel | E26: Canal | F26: Canalul prin care se vinde: Retail, Wholesale, Online, Direct, Partener. | G26: Recomandat | H26: Text | I26: Wholesale | J26: CRM | K26: Director Vânzări | M26: Mix de canal, oportunități cross-sell | N26: Nesolicitat
A27: D023 | B27: Clienți | C27: 10_CLIENTI | D27: Region | E27: Regiune / Țară | F27: Regiunea sau țara clientului. | G27: Recomandat | H27: Text | I27: București-Ilfov | J27: ERP / Facturare | K27: Sales Ops / CRM | M27: Analiză geografică | N27: Nesolicitat
A28: D024 | B28: Clienți | C28: 10_CLIENTI | D28: Country | E28: Țară | F28: Cod țară (RO, HU, BG...). | G28: Opțional | H28: Text | I28: RO | J28: ERP / Facturare | K28: Sales Ops / CRM | M28: Export vs. intern | N28: Nesolicitat
A29: D025 | B29: Clienți | C29: 10_CLIENTI | D29: Account_Owner_ID | E29: ID responsabil cont | F29: ID-ul persoanei din 12_OAMENI care răspunde de acest client. | G29: Recomandat | H29: Text | I29: S001 | J29: CRM | K29: Director Vânzări | M29: Analiză pe oameni, plan de acțiune | N29: Nesolicitat
A30: D026 | B30: Clienți | C30: 10_CLIENTI | D30: Customer_Since | E30: Client din data | F30: Data primei relații comerciale. | G30: Recomandat | H30: yyyy-mm-dd | I30: 2021-03-15 | J30: ERP / Facturare | K30: Sales Ops / CRM | M30: Vechime, retenție, clienți noi | N30: Nesolicitat
A31: D027 | B31: Clienți | C31: 10_CLIENTI | D31: Status | E31: Status | F31: Activ / Inactiv / Prospect / Pierdut. | G31: Recomandat | H31: Text | I31: Activ | J31: CRM | K31: Director Vânzări | M31: Reactivare clienți dormanți | N31: Nesolicitat
A32: D028 | B32: Clienți | C32: 10_CLIENTI | D32: Payment_Terms_Days | E32: Termen plată (zile) | F32: Termenul de plată agreat, în zile. | G32: Opțional | H32: #,##0 | I32: 30 | J32: Balanță / Contabilitate | K32: CFO / Contabilitate | M32: Cash-flow, risc | N32: Nesolicitat
A33: D029 | B33: Clienți | C33: 10_CLIENTI | D33: Credit_Limit | E33: Limită credit | F33: Plafonul de credit acordat. | G33: Opțional | H33: #,##0 | I33: 50000 | J33: Balanță / Contabilitate | K33: CFO / Contabilitate | M33: Risc comercial | N33: Nesolicitat
A34: D030 | B34: Clienți | C34: 10_CLIENTI | D34: Notes | E34: Observații | F34: Context util: istoric, relație, riscuri cunoscute. | G34: Opțional | H34: Text | I34: Renegociere contract în T3 | J34: Interviu / Workshop | K34: Director Vânzări | M34: Context pentru recomandări | N34: Nesolicitat
... A67: D063 | B67: Oameni | C67: 12_OAMENI | D67: Start_Date | E67: Data angajării | F67: Data intrării în echipă. | G67: Recomandat | H67: yyyy-mm-dd | I67: 2023-02-01 | J67: HR / State de plată | K67: HR / Resurse Umane | M67: FTE activ pe perioadă | N67: Nesolicitat
A68: D064 | B68: Oameni | C68: 12_OAMENI | D68: Exit_Date | E68: Data plecării | F68: Se lasă gol dacă persoana este activă. | G68: Recomandat | H68: yyyy-mm-dd | J68: HR / State de plată | K68: HR / Resurse Umane | M68: FTE activ, fluctuație | N68: Nesolicitat
A69: D065 | B69: Oameni | C69: 12_OAMENI | D69: Annual_Cost | E69: Cost anual total | F69: Cost total angajator pe an (opțional, se poate da agregat pe echipă). | G69: Opțional | H69: #,##0 | I69: 96000 | J69: HR / State de plată | K69: CFO / Contabilitate | M69: ROI pe om, cost/venit | N69: Nesolicitat
A70: D066 | B70: Oameni | C70: 12_OAMENI | D70: Is_Quota_Carrying | E70: Are țintă (Da/Nu) | F70: Dacă persoana are țintă de vânzări. | G70: Recomandat | H70: Text | I70: Da | J70: Director Vânzări | K70: Director Vânzări | M70: Atingere țintă pe om | N70: Nesolicitat

Sheet 04_DICTIONAR
A1: 04 — DICȚIONAR DE TERMENI
A2: Fiecare termen din fișier, explicat pe scurt, cu formularea pe care o poți folosi direct în discuția cu clientul. Filtrează pe „Categorie” ca să vezi doar ce te interesează.
A4: Termen | B4: Categorie | C4: Ce înseamnă | D4: De ce contează pentru analiză | E4: Cum îl ceri / unde îl găsești
A5: NDA (Non-Disclosure Agreement) | B5: Proces | C5: Acord de confidențialitate. Un contract scurt prin care te obligi să nu divulgi și să nu folosești în alt scop datele primite. | D5: Fără el, majoritatea firmelor serioase nu îți dau cifre reale. Îl semnezi înainte de prima cerere de date. | E5: „Vă propun să semnăm un acord de confidențialitate înainte să îmi trimiteți orice cifră. Aveți un model al dumneavoastră sau folosim al meu?”
A6: Kickoff | B6: Proces | C6: Întâlnirea de start a proiectului, în care stabilești obiectivul, perioada analizată, cine ce dă și până când. | D6: Aici completezi 01_FIRMA și 02_CONTACTE. Un kickoff bun scurtează colectarea cu săptămâni. | E6: „Propun o oră împreună la început, ca să stabilim exact ce ne uităm și cine îmi trimite ce.”
A7: Data kickoff | B7: Proces | C7: Data la care a avut loc întâlnirea de start. Este ziua zero a proiectului. | D7: De la ea numeri termenele. Dacă livrarea întârzie, de aici vezi unde s-a pierdut timpul. | E7: Se completează în 01_FIRMA, secțiunea MANDAT EQUIL.
A8: Data owner | B8: Proces | C8: Persoana din firmă care deține efectiv un set de date și îl poate scoate din sistem. | D8: Nu firma îți dă datele, ci un om anume. Foaia 02_CONTACTE există exact pentru asta. | E8: „Cine, concret, poate scoate din ERP lista de facturi pe ultimele 24 de luni?”
A9: Stakeholder / decident | B9: Proces | C9: Persoana care ia decizia finală și aprobă bugetele. Nu e întotdeauna cine te-a contactat. | D9: Raportul trebuie scris pentru decident. Dacă el nu e în discuție, concluziile rămân pe hârtie. | E9: „Cine semnează la final pentru acțiunile pe care le propunem?”
A10: Scope / mandat | B10: Proces | C10: Ce intră și ce NU intră în proiect: ce perioadă, ce linii de business, ce nu analizăm. | D10: Previne extinderea nelimitată a muncii („dar puteți să vă uitați și la...”). | E10: „Ne uităm la vânzări și clienți pe ultimele 24 de luni. Stocurile și producția nu intră acum.”
A11: Livrabil (deliverable) | B11: Proces | C11: Rezultatul concret pe care îl predai: în cazul nostru, raportul din 40_RAPORT plus planul de acțiuni. | D11: Clientul trebuie să știe din prima ce primește, ca să nu aibă alte așteptări. | E11: „La final primiți un raport cu 5 oportunități prioritizate și un plan pe 30 de zile.”
A12: Follow-up | B12: Proces | C12: Revenirea cu o solicitare sau o acțiune după o discuție. În colectarea de date, reamintirea politicoasă. | D12: Datele întârzie aproape întotdeauna. Două-trei follow-up-uri scurte sunt normale, nu insistență. | E12: „Vă reamintesc de exportul din ERP — de el depinde restul analizei. Puteți până vineri?”
A13: Workshop | B13: Proces | C13: Sesiune de lucru cu mai mulți oameni din firmă, în care validezi concluziile și construiești planul. | D13: Oportunitățile validate împreună cu echipa se execută. Cele trimise pe email, mai rar. | E13: „Propun 90 de minute cu echipa de vânzări, să validăm împreună ce am găsit.”
A14: GDPR | B14: Proces | C14: Regulamentul european de protecție a datelor personale. Numele, emailul sau telefonul unei persoane sunt date personale. | D14: Pentru NPS și pentru echipă, cere date anonimizate (inițiale sau ID-uri) dacă nu ai un temei clar. | E14: „Îmi puteți trimite lista cu inițiale în loc de nume complete? Analiza funcționează la fel.”
A15: ERP | B15: Sisteme | C15: Enterprise Resource Planning — programul central în care firma ține facturi, stocuri, furnizori, uneori contabilitatea. „Sistemul în care se face factura.” | D15: Sursa principală pentru vânzări, clienți, produse și costuri. Fără el, datele vin din Excel-uri paralele, cu erori. | E15: „În ce program emiteți facturile?” Exemple în România: SAGA, WinMentor, Smartbill, Nexus, Charisma, SAP, Oracle NetSuite.
... A70: Formatare condiționată | B70: Excel | C70: Colorarea automată a celulelor în funcție de valoare sau text. | D70: Prioritățile HIGH/MEDIUM/LOW și semnalele se colorează singure. | E70: —

Sheet 09_PARAMETRI
A1: 09 — PARAMETRI (panoul de control)
A2: Aici se setează perioada și pragurile. Tot restul fișierului se recalculează automat.
A4: PERIOADA DE ANALIZĂ
A5: Perioada curentă — de la | B5: 46023 | C5: Prima zi a perioadei analizate.
A6: Perioada curentă — până la | B6: 46203 | C6: Ultima zi a perioadei analizate.
A7: Perioada de comparație — de la | B7: 45658 | C7: De regulă aceeași perioadă din anul anterior.
A8: Perioada de comparație — până la | B8: 45838
A9: Data de referință | B9: =IF($B$6="",TODAY(),$B$6) | C9: Față de ea se numără zilele de inactivitate. Implicit = ultima zi a perioadei analizate, ca să nu apară dormanți artificiali când analizezi o perioadă din trecut. Poți scrie în loc =TODAY() sau o dată fixă.
A10: Moneda de raportare | B10: RON | C10: Toate valorile trebuie să fie în aceeași monedă.
A12: PRAGURI PENTRU SEMNALE
A13: Scădere de venit considerată alertă | B13: -0.15 | C13: Ex. −15%: sub acest nivel, clientul intră în „Scădere venit”.
A14: Creștere considerată oportunitate | B14: 0.2 | C14: Peste acest nivel, produsul/clientul e marcat ca „în creștere”.
A15: Marjă brută de referință | B15: 0.3 | C15: Sub acest nivel se semnalează problemă de marjă.
A16: Zile fără achiziție = client dormant | B16: 90 | C16: Numărul de zile de la ultima achiziție.
A17: Prag NPS acceptabil | B17: 30 | C17: NPS sub acest nivel declanșează plan de recuperare.
A18: Prag de atingere a țintei | B18: 0.9 | C18: Sub acest nivel se semnalează gap față de țintă.
A19: Concentrare: prag pe un singur client | B19: 0.2 | C19: Peste acest procent din venit, clientul e risc de concentrare.
A20: Venit minim pentru a intra în analiză | B20: 0 | C20: Ignoră clienții sub acest venit, ca să nu se aglomereze raportul.
A22: PRAGURI DE PRIORITIZARE A OPORTUNITĂȚILOR
A23: Scor minim pentru prioritate HIGH | B23: 40000 | C23: Scor = Impact × Probabilitate × Ușurință.
A24: Scor minim pentru prioritate MEDIUM | B24: 20000
A26: META
A27: Client analizat | B27: =IF('01_FIRMA'!B5="","[completează 01_FIRMA]",'01_FIRMA'!B5) | C27: Se preia din 01_FIRMA.
A28: Consultant EQUIL
A29: Versiune fișier | B29: v0.2
A30: Data generării raportului

Sheet 10_CLIENTI
A1: 10 — CLIENȚI (NOMENCLATOR)
A2: Galben = se completează. Gri = calculat automat, nu suprascrie.
A4: ID client Customer_ID | B4: Denumire client Customer_Name | C4: Segment Segment | D4: Canal Channel | E4: Regiune / Țară Region | F4: Țară Country | G4: ID responsabil cont Account_Owner_ID | H4: Client din data Customer_Since | I4: Status Status | J4: Termen plată (zile) Payment_Terms_Days | K4: Limită credit Credit_Limit | L4: Observații Notes
A5: C001 | B5: Alfa Distribution SRL | C5: Key Account | D5: Wholesale | E5: București-Ilfov | F5: RO | G5: S001 | H5: 44270 | I5: Activ | J5: 30 | K5: 50000 | L5: Exemplu — șterge înainte de utilizare
A6: C002 | B6: Beta Retail SA | C6: Mid-market | D6: Retail | E6: Cluj | F6: RO | G6: S002 | H6: 45078 | I6: Activ | J6: 15 | K6: 20000 | L6: Exemplu — șterge înainte de utilizare

Sheet 11_PRODUSE
A1: 11 — PRODUSE / SERVICII (NOMENCLATOR)
A2: Galben = se completează. Gri = calculat automat, nu suprascrie.
A4: ID produs Product_ID | B4: Denumire produs Product_Name | C4: Categorie Category | D4: Subcategorie Subcategory | E4: Preț de listă List_Price | F4: Cost standard Standard_Cost | G4: Recurent (Da/Nu) Is_Recurring | H4: Data lansării Launch_Date | I4: Status Status
A5: P001 | B5: Produs X | C5: Categoria A | E5: 120 | F5: 84 | G5: Nu | I5: Activ
A6: P002 | B6: Serviciu Y | C6: Servicii recurente | E6: 1200 | F6: 600 | G6: Da | I6: Activ

Sheet 12_OAMENI
A1: 12 — OAMENI (ECHIPA COMERCIALĂ / OPERAȚIONALĂ)
A2: Galben = se completează. Gri = calculat automat, nu suprascrie.
A4: ID persoană Person_ID | B4: Nume Person_Name | C4: Rol Role | D4: Echipă Team | E4: FTE (normă) FTE | F4: Data angajării Start_Date | G4: Data plecării Exit_Date | H4: Cost anual total Annual_Cost | I4: Are țintă (Da/Nu) Is_Quota_Carrying
A5: S001 | B5: Ana P. | C5: Key Account Manager | D5: Vânzări B2B | E5: 1 | F5: 44958 | H5: 96000 | I5: Da
A6: S002 | B6: Bogdan M. | C6: Sales Representative | D6: Vânzări B2B | E6: 1 | F6: 45536 | H6: 72000 | I6: Da

Sheet 13_VANZARI
A1: 13 — VÂNZĂRI / TRANZACȚII (FAPTIC)
A2: Galben = se completează. Gri = calculat automat, nu suprascrie.
A4: Data document Doc_Date | B4: Perioadă (AAAA-LL) Period | C4: Tip document Doc_Type | D4: ID client Customer_ID | E4: ID produs Product_ID | F4: ID persoană vânzări Person_ID | G4: Cantitate Units | H4: Venit net Revenue_Net | I4: Valoare discount Discount_Value | J4: Cost direct (COGS) COGS | K4: Profit brut Gross_Profit | L4: Marjă % Margin_Pct | M4: Denumire client Customer_Name | N4: Denumire produs Product_Name | O4: Monedă Currency | P4: Observații Notes
A5: 46053 | B5: =IF($A5="","",YEAR($A5)&"-"&RIGHT("0"&MONTH($A5),2)) | C5: Factură | D5: C001 | E5: P001 | F5: S001 | G5: 100 | H5: 10000 | I5: 0 | J5: 7500 | K5: =IF($H5="","",$H5-N($J5)) | L5: =IFERROR($K5/$H5,"") | M5: =IFERROR(INDEX('10_CLIENTI'!$B$5:$B$204,MATCH($D5,'10_CLIENTI'!$A$5:$A$204,0)),"") | N5: =IFERROR(INDEX('11_PRODUSE'!$B$5:$B$104,MATCH($E5,'11_PRODUSE'!$A$5:$A$104,0)),"") | O5: RON | P5: Exemplu — șterge înainte de utilizare
A6: 46053 | B6: =IF($A6="","",YEAR($A6)&"-"&RIGHT("0"&MONTH($A6),2)) | C6: Factură | D6: C002 | E6: P002 | F6: S002 | G6: 10 | H6: 12000 | I6: 500 | J6: 6000 | K6: =IF($H6="","",$H6-N($J6)) | L6: =IFERROR($K6/$H6,"") | M6: =IFERROR(INDEX('10_CLIENTI'!$B$5:$B$204,MATCH($D6,'10_CLIENTI'!$A$5:$A$204,0)),"") | N6: =IFERROR(INDEX('11_PRODUSE'!$B$5:$B$104,MATCH($E6,'11_PRODUSE'!$A$5:$A$104,0)),"") | O6: RON | P6: Exemplu — șterge înainte de utilizare
B7: =IF($A7="","",YEAR($A7)&"-"&RIGHT("0"&MONTH($A7),2)) | K7: =IF($H7="","",$H7-N($J7)) | L7: =IFERROR($K7/$H7,"") | M7: =IFERROR(INDEX('10_CLIENTI'!$B$5:$B$204,MATCH($D7,'10_CLIENTI'!$A$5:$A$204,0)),"") | N7: =IFERROR(INDEX('11_PRODUSE'!$B$5:$B$104,MATCH($E7,'11_PRODUSE'!$A$5:$A$104,0)),"")
B8: =IF($A8="","",YEAR($A8)&"-"&RIGHT("0"&MONTH($A8),2)) | K8: =IF($H8="","",$H8-N($J8)) | L8: =IFERROR($K8/$H8,"") | M8: =IFERROR(INDEX('10_CLIENTI'!$B$5:$B$204,MATCH($D8,'10_CLIENTI'!$A$5:$A$204,0)),"") | N8: =IFERROR(INDEX('11_PRODUSE'!$B$5:$B$104,MATCH($E8,'11_PRODUSE'!$A$5:$A$104,0)),"")
B9: =IF($A9="","",YEAR($A9)&"-"&RIGHT("0"&MONTH($A9),2)) | K9: =IF($H9="","",$H9-N($J9)) | L9: =IFERROR($K9/$H9,"") | M9: =IFERROR(INDEX('10_CLIENTI'!$B$5:$B$204,MATCH($D9,'10_CLIENTI'!$A$5:$A$204,0)),"") | N9: =IFERROR(INDEX('11_PRODUSE'!$B$5:$B$104,MATCH($E9,'11_PRODUSE'!$A$5:$A$104,0)),"")
B10: =IF($A10="","",YEAR($A10)&"-"&RIGHT("0"&MONTH($A10),2)) | K10: =IF($H10="","",$H10-N($J10)) | L10: =IFERROR($K10/$H10,"") | M10: =IFERROR(INDEX('10_CLIENTI'!$B$5:$B$204,MATCH($D10,'10_CLIENTI'!$A$5:$A$204,0)),"") | N10: =IFERROR(INDEX('11_PRODUSE'!$B$5:$B$104,MATCH($E10,'11_PRODUSE'!$A$5:$A$104,0)),"")
B11: =IF($A11="","",YEAR($A11)&"-"&RIGHT("0"&MONTH($A11),2)) | K11: =IF($H11="","",$H11-N($J11)) | L11: =IFERROR($K11/$H11,"") | M11: =IFERROR(INDEX('10_CLIENTI'!$B$5:$B$204,MATCH($D11,'10_CLIENTI'!$A$5:$A$204,0)),"") | N11: =IFERROR(INDEX('11_PRODUSE'!$B$5:$B$104,MATCH($E11,'11_PRODUSE'!$A$5:$A$104,0)),"")
B12: =IF($A12="","",YEAR($A12)&"-"&RIGHT("0"&MONTH($A12),2)) | K12: =IF($H12="","",$H12-N($J12)) | L12: =IFERROR($K12/$H12,"") | M12: =IFERROR(INDEX('10_CLIENTI'!$B$5:$B$204,MATCH($D12,'10_CLIENTI'!$A$5:$A$204,0)),"") | N12: =IFERROR(INDEX('11_PRODUSE'!$B$5:$B$104,MATCH($E12,'11_PRODUSE'!$A$5:$A$104,0)),"")
B13: =IF($A13="","",YEAR($A13)&"-"&RIGHT("0"&MONTH($A13),2)) | K13: =IF($H13="","",$H13-N($J13)) | L13: =IFERROR($K13/$H13,"") | M13: =IFERROR(INDEX('10_CLIENTI'!$B$5:$B$204,MATCH($D13,'10_CLIENTI'!$A$5:$A$204,0)),"") | N13: =IFERROR(INDEX('11_PRODUSE'!$B$5:$B$104,MATCH($E13,'11_PRODUSE'!$A$5:$A$104,0)),"")
B14: =IF($A14="","",YEAR($A14)&"-"&RIGHT("0"&MONTH($A14),2)) | K14: =IF($H14="","",$H14-N($J14)) | L14: =IFERROR($K14/$H14,"") | M14: =IFERROR(INDEX('10_CLIENTI'!$B$5:$B$204,MATCH($D14,'10_CLIENTI'!$A$5:$A$204,0)),"") | N14: =IFERROR(INDEX('11_PRODUSE'!$B$5:$B$104,MATCH($E14,'11_PRODUSE'!$A$5:$A$104,0)),"")
B15: =IF($A15="","",YEAR($A15)&"-"&RIGHT("0"&MONTH($A15),2)) | K15: =IF($H15="","",$H15-N($J15)) | L15: =IFERROR($K15/$H15,"") | M15: =IFERROR(INDEX('10_CLIENTI'!$B$5:$B$204,MATCH($D15,'10_CLIENTI'!$A$5:$A$204,0)),"") | N15: =IFERROR(INDEX('11_PRODUSE'!$B$5:$B$104,MATCH($E15,'11_PRODUSE'!$A$5:$A$104,0)),"")
B16: =IF($A16="","",YEAR($A16)&"-"&RIGHT("0"&MONTH($A16),2)) | K16: =IF($H16="","",$H16-N($J16)) | L16: =IFERROR($K16/$H16,"") | M16: =IFERROR(INDEX('10_CLIENTI'!$B$5:$B$204,MATCH($D16,'10_CLIENTI'!$A$5:$A$204,0)),"") | N16: =IFERROR(INDEX('11_PRODUSE'!$B$5:$B$104,MATCH($E16,'11_PRODUSE'!$A$5:$A$104,0)),"")
B17: =IF($A17="","",YEAR($A17)&"-"&RIGHT("0"&MONTH($A17),2)) | K17: =IF($H17="","",$H17-N($J17)) | L17: =IFERROR($K17/$H17,"") | M17: =IFERROR(INDEX('10_CLIENTI'!$B$5:$B$204,MATCH($D17,'10_CLIENTI'!$A$5:$A$204,0)),"") | N17: =IFERROR(INDEX('11_PRODUSE'!$B$5:$B$104,MATCH($E17,'11_PRODUSE'!$A$5:$A$104,0)),"")
B18: =IF($A18="","",YEAR($A18)&"-"&RIGHT("0"&MONTH($A18),2)) | K18: =IF($H18="","",$H18-N($J18)) | L18: =IFERROR($K18/$H18,"") | M18: =IFERROR(INDEX('10_CLIENTI'!$B$5:$B$204,MATCH($D18,'10_CLIENTI'!$A$5:$A$204,0)),"") | N18: =IFERROR(INDEX('11_PRODUSE'!$B$5:$B$104,MATCH($E18,'11_PRODUSE'!$A$5:$A$104,0)),"")
... B1004: =IF($A1004="","",YEAR($A1004)&"-"&RIGHT("0"&MONTH($A1004),2)) | K1004: =IF($H1004="","",$H1004-N($J1004)) | L1004: =IFERROR($K1004/$H1004,"") | M1004: =IFERROR(INDEX('10_CLIENTI'!$B$5:$B$204,MATCH($D1004,'10_CLIENTI'!$A$5:$A$204,0)),"") | N1004: =IFERROR(INDEX('11_PRODUSE'!$B$5:$B$104,MATCH($E1004,'11_PRODUSE'!$A$5:$A$104,0)),"")

Sheet 14_TINTE
A1: 14 — ȚINTE / BUGET
A2: Galben = se completează. Gri = calculat automat, nu suprascrie.
A4: Perioadă (data) Period_Date | B4: Nivel țintă Scope | C4: ID nivel Scope_ID | D4: Indicator Metric | E4: Valoare țintă Target_Value | F4: Observații Notes
A5: 46053 | B5: Companie | D5: Venit | E5: 120000 | F5: Exemplu — șterge înainte de utilizare

Sheet 15_NPS
A1: 15 — NPS / FEEDBACK CLIENȚI
A2: Galben = se completează. Gri = calculat automat, nu suprascrie.
A4: ID răspuns Response_ID | B4: Data răspunsului Survey_Date | C4: ID client Customer_ID | D4: Nume respondent Respondent_Name | E4: Rol respondent Respondent_Role | F4: Scor NPS (0-10) Score | G4: Categorie NPS_Category | H4: Motivul scorului Reason | I4: Temă Theme | J4: Canal colectare Channel | K4: Val / campanie Survey_Wave | L4: Responsabil follow-up Follow_Up_Owner | M4: Status follow-up Follow_Up_Status
A5: R0001 | B5: 46063 | C5: C001 | D5: Mihai I. | E5: Decident | F5: 9 | G5: =IF($F5="","",IF($F5>=9,"Promotor",IF($F5>=7,"Pasiv","Detractor"))) | H5: Relație bună, livrări la timp | I5: Relație | J5: Email | K5: 2026-T1 | L5: S001 | M5: Neînceput
A6: R0002 | B6: 46065 | C6: C002 | D6: Ioana R. | E6: Utilizator | F6: 5 | G6: =IF($F6="","",IF($F6>=9,"Promotor",IF($F6>=7,"Pasiv","Detractor"))) | H6: Întârzieri repetate la livrare | I6: Livrare | J6: Email | K6: 2026-T1 | L6: S002 | M6: În lucru
G7: =IF($F7="","",IF($F7>=9,"Promotor",IF($F7>=7,"Pasiv","Detractor")))
G8: =IF($F8="","",IF($F8>=9,"Promotor",IF($F8>=7,"Pasiv","Detractor")))
G9: =IF($F9="","",IF($F9>=9,"Promotor",IF($F9>=7,"Pasiv","Detractor")))
G10: =IF($F10="","",IF($F10>=9,"Promotor",IF($F10>=7,"Pasiv","Detractor")))
G11: =IF($F11="","",IF($F11>=9,"Promotor",IF($F11>=7,"Pasiv","Detractor")))
G12: =IF($F12="","",IF($F12>=9,"Promotor",IF($F12>=7,"Pasiv","Detractor")))
G13: =IF($F13="","",IF($F13>=9,"Promotor",IF($F13>=7,"Pasiv","Detractor")))
G14: =IF($F14="","",IF($F14>=9,"Promotor",IF($F14>=7,"Pasiv","Detractor")))
G15: =IF($F15="","",IF($F15>=9,"Promotor",IF($F15>=7,"Pasiv","Detractor")))
G16: =IF($F16="","",IF($F16>=9,"Promotor",IF($F16>=7,"Pasiv","Detractor")))
G17: =IF($F17="","",IF($F17>=9,"Promotor",IF($F17>=7,"Pasiv","Detractor")))
G18: =IF($F18="","",IF($F18>=9,"Promotor",IF($F18>=7,"Pasiv","Detractor")))
... G504: =IF($F504="","",IF($F504>=9,"Promotor",IF($F504>=7,"Pasiv","Detractor")))

Sheet 20_KPI
A1: 20 — KPI (perioada curentă vs. perioada de comparație)
A2: Toate valorile se recalculează din 09_PARAMETRI. Nu se scrie nimic în această foaie.
B3: ='09_PARAMETRI'!$B$5 | C3: ='09_PARAMETRI'!$B$7
A4: KPI | B4: Perioada curentă | C4: Perioada comparativă | D4: Δ | E4: Δ % | F4: Ce înseamnă
A5: VENIT ȘI PROFIT
A6: Venit net | B6: =SUMIFS('13_VANZARI'!$H$5:$H$1004,'13_VANZARI'!$A$5:$A$1004,">="&'09_PARAMETRI'!$B$5,'13_VANZARI'!$A$5:$A$1004,"<="&'09_PARAMETRI'!$B$6) | C6: =SUMIFS('13_VANZARI'!$H$5:$H$1004,'13_VANZARI'!$A$5:$A$1004,">="&'09_PARAMETRI'!$B$7,'13_VANZARI'!$A$5:$A$1004,"<="&'09_PARAMETRI'!$B$8) | D6: =IFERROR(IF(OR(B6="",C6=""),"",B6-C6),"") | E6: =IFERROR(IF(OR(C6=0,C6=""),"",(B6-C6)/ABS(C6)),"") | F6: Venitul total fără TVA din perioada selectată.
A7: Profit brut | B7: =SUMIFS('13_VANZARI'!$K$5:$K$1004,'13_VANZARI'!$A$5:$A$1004,">="&'09_PARAMETRI'!$B$5,'13_VANZARI'!$A$5:$A$1004,"<="&'09_PARAMETRI'!$B$6) | C7: =SUMIFS('13_VANZARI'!$K$5:$K$1004,'13_VANZARI'!$A$5:$A$1004,">="&'09_PARAMETRI'!$B$7,'13_VANZARI'!$A$5:$A$1004,"<="&'09_PARAMETRI'!$B$8) | D7: =IFERROR(IF(OR(B7="",C7=""),"",B7-C7),"") | E7: =IFERROR(IF(OR(C7=0,C7=""),"",(B7-C7)/ABS(C7)),"") | F7: Venit net minus costurile directe.
A8: Marjă brută % | B8: =IFERROR(SUMIFS('13_VANZARI'!$K$5:$K$1004,'13_VANZARI'!$A$5:$A$1004,">="&'09_PARAMETRI'!$B$5,'13_VANZARI'!$A$5:$A$1004,"<="&'09_PARAMETRI'!$B$6)/SUMIFS('13_VANZARI'!$H$5:$H$1004,'13_VANZARI'!$A$5:$A$1004,">="&'09_PARAMETRI'!$B$5,'13_VANZARI'!$A$5:$A$1004,"<="&'09_PARAMETRI'!$B$6),0) | C8: =IFERROR(SUMIFS('13_VANZARI'!$K$5:$K$1004,'13_VANZARI'!$A$5:$A$1004,">="&'09_PARAMETRI'!$B$7,'13_VANZARI'!$A$5:$A$1004,"<="&'09_PARAMETRI'!$B$8)/SUMIFS('13_VANZARI'!$H$5:$H$1004,'13_VANZARI'!$A$5:$A$1004,">="&'09_PARAMETRI'!$B$7,'13_VANZARI'!$A$5:$A$1004,"<="&'09_PARAMETRI'!$B$8),0) | D8: =IFERROR(IF(OR(B8="",C8=""),"",B8-C8),"") | E8: — | F8: Profit brut / venit net. Compară cu pragul din 09_PARAMETRI.
A9: Discount acordat | B9: =SUMIFS('13_VANZARI'!$I$5:$I$1004,'13_VANZARI'!$A$5:$A$1004,">="&'09_PARAMETRI'!$B$5,'13_VANZARI'!$A$5:$A$1004,"<="&'09_PARAMETRI'!$B$6) | C9: =SUMIFS('13_VANZARI'!$I$5:$I$1004,'13_VANZARI'!$A$5:$A$1004,">="&'09_PARAMETRI'!$B$7,'13_VANZARI'!$A$5:$A$1004,"<="&'09_PARAMETRI'!$B$8) | D9: =IFERROR(IF(OR(B9="",C9=""),"",B9-C9),"") | E9: =IFERROR(IF(OR(C9=0,C9=""),"",(B9-C9)/ABS(C9)),"") | F9: Cât s-a lăsat din preț. Creșterea lui erodează marja.
A10: Unități vândute | B10: =SUMIFS('13_VANZARI'!$G$5:$G$1004,'13_VANZARI'!$A$5:$A$1004,">="&'09_PARAMETRI'!$B$5,'13_VANZARI'!$A$5:$A$1004,"<="&'09_PARAMETRI'!$B$6) | C10: =SUMIFS('13_VANZARI'!$G$5:$G$1004,'13_VANZARI'!$A$5:$A$1004,">="&'09_PARAMETRI'!$B$7,'13_VANZARI'!$A$5:$A$1004,"<="&'09_PARAMETRI'!$B$8) | D10: =IFERROR(IF(OR(B10="",C10=""),"",B10-C10),"") | E10: =IFERROR(IF(OR(C10=0,C10=""),"",(B10-C10)/ABS(C10)),"") | F10: Separă creșterea de volum de creșterea de preț.
A11: Preț mediu / unitate | B11: =IFERROR(SUMIFS('13_VANZARI'!$H$5:$H$1004,'13_VANZARI'!$A$5:$A$1004,">="&'09_PARAMETRI'!$B$5,'13_VANZARI'!$A$5:$A$1004,"<="&'09_PARAMETRI'!$B$6)/SUMIFS('13_VANZARI'!$G$5:$G$1004,'13_VANZARI'!$A$5:$A$1004,">="&'09_PARAMETRI'!$B$5,'13_VANZARI'!$A$5:$A$1004,"<="&'09_PARAMETRI'!$B$6),0) | C11: =IFERROR(SUMIFS('13_VANZARI'!$H$5:$H$1004,'13_VANZARI'!$A$5:$A$1004,">="&'09_PARAMETRI'!$B$7,'13_VANZARI'!$A$5:$A$1004,"<="&'09_PARAMETRI'!$B$8)/SUMIFS('13_VANZARI'!$G$5:$G$1004,'13_VANZARI'!$A$5:$A$1004,">="&'09_PARAMETRI'!$B$7,'13_VANZARI'!$A$5:$A$1004,"<="&'09_PARAMETRI'!$B$8),0) | D11: =IFERROR(IF(OR(B11="",C11=""),"",B11-C11),"") | E11: =IFERROR(IF(OR(C11=0,C11=""),"",(B11-C11)/ABS(C11)),"") | F11: Venit net / unități. Arată dacă prețul crește sau se erodează.
A12: CLIENȚI
A13: Clienți activi | B13: =SUMPRODUCT(('10_CLIENTI'!$A$5:$A$204<>"")*(SUMIFS('13_VANZARI'!$H$5:$H$1004,'13_VANZARI'!$D$5:$D$1004,'10_CLIENTI'!$A$5:$A$204,'13_VANZARI'!$A$5:$A$1004,">="&'09_PARAMETRI'!$B$5,'13_VANZARI'!$A$5:$A$1004,"<="&'09_PARAMETRI'!$B$6)<>0)) | C13: =SUMPRODUCT(('10_CLIENTI'!$A$5:$A$204<>"")*(SUMIFS('13_VANZARI'!$H$5:$H$1004,'13_VANZARI'!$D$5:$D$1004,'10_CLIENTI'!$A$5:$A$204,'13_VANZARI'!$A$5:$A$1004,">="&'09_PARAMETRI'!$B$7,'13_VANZARI'!$A$5:$A$1004,"<="&'09_PARAMETRI'!$B$8)<>0)) | D13: =IFERROR(IF(OR(B13="",C13=""),"",B13-C13),"") | E13: =IFERROR(IF(OR(C13=0,C13=""),"",(B13-C13)/ABS(C13)),"") | F13: Clienți cu cel puțin o tranzacție în perioadă.
A14: Clienți noi | B14: =SUMPRODUCT(('10_CLIENTI'!$A$5:$A$204<>"")*(SUMIFS('13_VANZARI'!$H$5:$H$1004,'13_VANZARI'!$D$5:$D$1004,'10_CLIENTI'!$A$5:$A$204,'13_VANZARI'!$A$5:$A$1004,"<"&'09_PARAMETRI'!$B$5)=0)*(SUMIFS('13_VANZARI'!$H$5:$H$1004,'13_VANZARI'!$D$5:$D$1004,'10_CLIENTI'!$A$5:$A$204,'13_VANZARI'!$A$5:$A$1004,">="&'09_PARAMETRI'!$B$5,'13_VANZARI'!$A$5:$A$1004,"<="&'09_PARAMETRI'!$B$6)<>0)) | C14: =SUMPRODUCT(('10_CLIENTI'!$A$5:$A$204<>"")*(SUMIFS('13_VANZARI'!$H$5:$H$1004,'13_VANZARI'!$D$5:$D$1004,'10_CLIENTI'!$A$5:$A$204,'13_VANZARI'!$A$5:$A$1004,"<"&'09_PARAMETRI'!$B$7)=0)*(SUMIFS('13_VANZARI'!$H$5:$H$1004,'13_VANZARI'!$D$5:$D$1004,'10_CLIENTI'!$A$5:$A$204,'13_VANZARI'!$A$5:$A$1004,">="&'09_PARAMETRI'!$B$7,'13_VANZARI'!$A$5:$A$1004,"<="&'09_PARAMETRI'!$B$8)<>0)) | D14: =IFERROR(IF(OR(B14="",C14=""),"",B14-C14),"") | E14: =IFERROR(IF(OR(C14=0,C14=""),"",(B14-C14)/ABS(C14)),"") | F14: Clienți fără nicio achiziție înainte de perioada curentă.
A15: Venit mediu / client | B15: =IFERROR(SUMIFS('13_VANZARI'!$H$5:$H$1004,'13_VANZARI'!$A$5:$A$1004,">="&'09_PARAMETRI'!$B$5,'13_VANZARI'!$A$5:$A$1004,"<="&'09_PARAMETRI'!$B$6)/(SUMPRODUCT(('10_CLIENTI'!$A$5:$A$204<>"")*(SUMIFS('13_VANZARI'!$H$5:$H$1004,'13_VANZARI'!$D$5:$D$1004,'10_CLIENTI'!$A$5:$A$204,'13_VANZARI'!$A$5:$A$1004,">="&'09_PARAMETRI'!$B$5,'13_VANZARI'!$A$5:$A$1004,"<="&'09_PARAMETRI'!$B$6)<>0))),0) | C15: =IFERROR(SUMIFS('13_VANZARI'!$H$5:$H$1004,'13_VANZARI'!$A$5:$A$1004,">="&'09_PARAMETRI'!$B$7,'13_VANZARI'!$A$5:$A$1004,"<="&'09_PARAMETRI'!$B$8)/(SUMPRODUCT(('10_CLIENTI'!$A$5:$A$204<>"")*(SUMIFS('13_VANZARI'!$H$5:$H$1004,'13_VANZARI'!$D$5:$D$1004,'10_CLIENTI'!$A$5:$A$204,'13_VANZARI'!$A$5:$A$1004,">="&'09_PARAMETRI'!$B$7,'13_VANZARI'!$A$5:$A$1004,"<="&'09_PARAMETRI'!$B$8)<>0))),0) | D15: =IFERROR(IF(OR(B15="",C15=""),"",B15-C15),"") | E15: =IFERROR(IF(OR(C15=0,C15=""),"",(B15-C15)/ABS(C15)),"") | F15: Arată dacă creșterea vine din clienți noi sau din adâncirea relației.
A16: Număr de linii / facturi | B16: =SUMPRODUCT(('13_VANZARI'!$A$5:$A$1004>='09_PARAMETRI'!$B$5)*('13_VANZARI'!$A$5:$A$1004<='09_PARAMETRI'!$B$6)*('13_VANZARI'!$H$5:$H$1004<>"")) | C16: =SUMPRODUCT(('13_VANZARI'!$A$5:$A$1004>='09_PARAMETRI'!$B$7)*('13_VANZARI'!$A$5:$A$1004<='09_PARAMETRI'!$B$8)*('13_VANZARI'!$H$5:$H$1004<>"")) | D16: =IFERROR(IF(OR(B16="",C16=""),"",B16-C16),"") | E16: =IFERROR(IF(OR(C16=0,C16=""),"",(B16-C16)/ABS(C16)),"") | F16: Frecvența comenzilor.
A17: Valoare medie per linie | B17: =IFERROR(SUMIFS('13_VANZARI'!$H$5:$H$1004,'13_VANZARI'!$A$5:$A$1004,">="&'09_PARAMETRI'!$B$5,'13_VANZARI'!$A$5:$A$1004,"<="&'09_PARAMETRI'!$B$6)/(SUMPRODUCT(('13_VANZARI'!$A$5:$A$1004>='09_PARAMETRI'!$B$5)*('13_VANZARI'!$A$5:$A$1004<='09_PARAMETRI'!$B$6)*('13_VANZARI'!$H$5:$H$1004<>""))),0) | C17: =IFERROR(SUMIFS('13_VANZARI'!$H$5:$H$1004,'13_VANZARI'!$A$5:$A$1004,">="&'09_PARAMETRI'!$B$7,'13_VANZARI'!$A$5:$A$1004,"<="&'09_PARAMETRI'!$B$8)/(SUMPRODUCT(('13_VANZARI'!$A$5:$A$1004>='09_PARAMETRI'!$B$7)*('13_VANZARI'!$A$5:$A$1004<='09_PARAMETRI'!$B$8)*('13_VANZARI'!$H$5:$H$1004<>""))),0) | D17: =IFERROR(IF(OR(B17="",C17=""),"",B17-C17),"") | E17: =IFERROR(IF(OR(C17=0,C17=""),"",(B17-C17)/ABS(C17)),"") | F17: Venit net / număr de linii.
A18: Concentrare — cel mai mare client | B18: =IFERROR(SUMPRODUCT(MAX(('10_CLIENTI'!$A$5:$A$204<>"")*SUMIFS('13_VANZARI'!$H$5:$H$1004,'13_VANZARI'!$D$5:$D$1004,'10_CLIENTI'!$A$5:$A$204,'13_VANZARI'!$A$5:$A$1004,">="&'09_PARAMETRI'!$B$5,'13_VANZARI'!$A$5:$A$1004,"<="&'09_PARAMETRI'!$B$6)))/SUMIFS('13_VANZARI'!$H$5:$H$1004,'13_VANZARI'!$A$5:$A$1004,">="&'09_PARAMETRI'!$B$5,'13_VANZARI'!$A$5:$A$1004,"<="&'09_PARAMETRI'!$B$6),0) | C18: =IFERROR(SUMPRODUCT(MAX(('10_CLIENTI'!$A$5:$A$204<>"")*SUMIFS('13_VANZARI'!$H$5:$H$1004,'13_VANZARI'!$D$5:$D$1004,'10_CLIENTI'!$A$5:$A$204,'13_VANZARI'!$A$5:$A$1004,">="&'09_PARAMETRI'!$B$7,'13_VANZARI'!$A$5:$A$1004,"<="&'09_PARAMETRI'!$B$8)))/SUMIFS('13_VANZARI'!$H$5:$H$1004,'13_VANZARI'!$A$5:$A$1004,">="&'09_PARAMETRI'!$B$7,'13_VANZARI'!$A$5:$A$1004,"<="&'09_PARAMETRI'!$B$8),0) | D18: =IFERROR(IF(OR(B18="",C18=""),"",B18-C18),"") | E18: — | F18: Ce procent din venit vine de la un singur client. Peste pragul setat = risc.
A19: OAMENI
A20: FTE activ | B20: =SUMPRODUCT(('12_OAMENI'!$A$5:$A$64<>"")*('12_OAMENI'!$F$5:$F$64<='09_PARAMETRI'!$B$6)*(('12_OAMENI'!$G$5:$G$64="")+('12_OAMENI'!$G$5:$G$64>='09_PARAMETRI'!$B$5))*'12_OAMENI'!$E$5:$E$64) | C20: =SUMPRODUCT(('12_OAMENI'!$A$5:$A$64<>"")*('12_OAMENI'!$F$5:$F$64<='09_PARAMETRI'!$B$8)*(('12_OAMENI'!$G$5:$G$64="")+('12_OAMENI'!$G$5:$G$64>='09_PARAMETRI'!$B$7))*'12_OAMENI'!$E$5:$E$64) | D20: =IFERROR(IF(OR(B20="",C20=""),"",B20-C20),"") | E20: =IFERROR(IF(OR(C20=0,C20=""),"",(B20-C20)/ABS(C20)),"") | F20: Normă întreagă echivalentă, activă în perioadă.
A21: Venit / FTE | B21: =IFERROR(SUMIFS('13_VANZARI'!$H$5:$H$1004,'13_VANZARI'!$A$5:$A$1004,">="&'09_PARAMETRI'!$B$5,'13_VANZARI'!$A$5:$A$1004,"<="&'09_PARAMETRI'!$B$6)/(SUMPRODUCT(('12_OAMENI'!$A$5:$A$64<>"")*('12_OAMENI'!$F$5:$F$64<='09_PARAMETRI'!$B$6)*(('12_OAMENI'!$G$5:$G$64="")+('12_OAMENI'!$G$5:$G$64>='09_PARAMETRI'!$B$5))*'12_OAMENI'!$E$5:$E$64)),0) | C21: =IFERROR(SUMIFS('13_VANZARI'!$H$5:$H$1004,'13_VANZARI'!$A$5:$A$1004,">="&'09_PARAMETRI'!$B$7,'13_VANZARI'!$A$5:$A$1004,"<="&'09_PARAMETRI'!$B$8)/(SUMPRODUCT(('12_OAMENI'!$A$5:$A$64<>"")*('12_OAMENI'!$F$5:$F$64<='09_PARAMETRI'!$B$8)*(('12_OAMENI'!$G$5:$G$64="")+('12_OAMENI'!$G$5:$G$64>='09_PARAMETRI'!$B$7))*'12_OAMENI'!$E$5:$E$64)),0) | D21: =IFERROR(IF(OR(B21="",C21=""),"",B21-C21),"") | E21: =IFERROR(IF(OR(C21=0,C21=""),"",(B21-C21)/ABS(C21)),"") | F21: Indicatorul principal de productivitate.
A22: Profit brut / FTE | B22: =IFERROR(SUMIFS('13_VANZARI'!$K$5:$K$1004,'13_VANZARI'!$A$5:$A$1004,">="&'09_PARAMETRI'!$B$5,'13_VANZARI'!$A$5:$A$1004,"<="&'09_PARAMETRI'!$B$6)/(SUMPRODUCT(('12_OAMENI'!$A$5:$A$64<>"")*('12_OAMENI'!$F$5:$F$64<='09_PARAMETRI'!$B$6)*(('12_OAMENI'!$G$5:$G$64="")+('12_OAMENI'!$G$5:$G$64>='09_PARAMETRI'!$B$5))*'12_OAMENI'!$E$5:$E$64)),0) | C22: =IFERROR(SUMIFS('13_VANZARI'!$K$5:$K$1004,'13_VANZARI'!$A$5:$A$1004,">="&'09_PARAMETRI'!$B$7,'13_VANZARI'!$A$5:$A$1004,"<="&'09_PARAMETRI'!$B$8)/(SUMPRODUCT(('12_OAMENI'!$A$5:$A$64<>"")*('12_OAMENI'!$F$5:$F$64<='09_PARAMETRI'!$B$8)*(('12_OAMENI'!$G$5:$G$64="")+('12_OAMENI'!$G$5:$G$64>='09_PARAMETRI'!$B$7))*'12_OAMENI'!$E$5:$E$64)),0) | D22: =IFERROR(IF(OR(B22="",C22=""),"",B22-C22),"") | E22: =IFERROR(IF(OR(C22=0,C22=""),"",(B22-C22)/ABS(C22)),"") | F22: Productivitate ajustată cu marja.
A23: EXPERIENȚA CLIENTULUI
A24: NPS | B24: =IFERROR(((COUNTIFS('15_NPS'!$B$5:$B$504,">="&'09_PARAMETRI'!$B$5,'15_NPS'!$B$5:$B$504,"<="&'09_PARAMETRI'!$B$6,'15_NPS'!$F$5:$F$504,">=9"))-(COUNTIFS('15_NPS'!$B$5:$B$504,">="&'09_PARAMETRI'!$B$5,'15_NPS'!$B$5:$B$504,"<="&'09_PARAMETRI'!$B$6,'15_NPS'!$F$5:$F$504,"<=6")))/(SUMPRODUCT(('15_NPS'!$B$5:$B$504>='09_PARAMETRI'!$B$5)*('15_NPS'!$B$5:$B$504<='09_PARAMETRI'!$B$6)*('15_NPS'!$F$5:$F$504<>"")))*100,"") | C24: =IFERROR(((COUNTIFS('15_NPS'!$B$5:$B$504,">="&'09_PARAMETRI'!$B$7,'15_NPS'!$B$5:$B$504,"<="&'09_PARAMETRI'!$B$8,'15_NPS'!$F$5:$F$504,">=9"))-(COUNTIFS('15_NPS'!$B$5:$B$504,">="&'09_PARAMETRI'!$B$7,'15_NPS'!$B$5:$B$504,"<="&'09_PARAMETRI'!$B$8,'15_NPS'!$F$5:$F$504,"<=6")))/(SUMPRODUCT(('15_NPS'!$B$5:$B$504>='09_PARAMETRI'!$B$7)*('15_NPS'!$B$5:$B$504<='09_PARAMETRI'!$B$8)*('15_NPS'!$F$5:$F$504<>"")))*100,"") | D24: =IFERROR(IF(OR(B24="",C24=""),"",B24-C24),"") | E24: =IFERROR(IF(OR(C24=0,C24=""),"",(B24-C24)/ABS(C24)),"") | F24: (% promotori − % detractori) × 100. Scala: −100 la +100.
A25: Număr răspunsuri NPS | B25: =SUMPRODUCT(('15_NPS'!$B$5:$B$504>='09_PARAMETRI'!$B$5)*('15_NPS'!$B$5:$B$504<='09_PARAMETRI'!$B$6)*('15_NPS'!$F$5:$F$504<>"")) | C25: =SUMPRODUCT(('15_NPS'!$B$5:$B$504>='09_PARAMETRI'!$B$7)*('15_NPS'!$B$5:$B$504<='09_PARAMETRI'!$B$8)*('15_NPS'!$F$5:$F$504<>"")) | D25: =IFERROR(IF(OR(B25="",C25=""),"",B25-C25),"") | E25: =IFERROR(IF(OR(C25=0,C25=""),"",(B25-C25)/ABS(C25)),"") | F25: Sub 20 de răspunsuri, NPS-ul e orientativ, nu concluziv.
A26: % Promotori | B26: =IFERROR((COUNTIFS('15_NPS'!$B$5:$B$504,">="&'09_PARAMETRI'!$B$5,'15_NPS'!$B$5:$B$504,"<="&'09_PARAMETRI'!$B$6,'15_NPS'!$F$5:$F$504,">=9"))/(SUMPRODUCT(('15_NPS'!$B$5:$B$504>='09_PARAMETRI'!$B$5)*('15_NPS'!$B$5:$B$504<='09_PARAMETRI'!$B$6)*('15_NPS'!$F$5:$F$504<>""))),"") | C26: =IFERROR((COUNTIFS('15_NPS'!$B$5:$B$504,">="&'09_PARAMETRI'!$B$7,'15_NPS'!$B$5:$B$504,"<="&'09_PARAMETRI'!$B$8,'15_NPS'!$F$5:$F$504,">=9"))/(SUMPRODUCT(('15_NPS'!$B$5:$B$504>='09_PARAMETRI'!$B$7)*('15_NPS'!$B$5:$B$504<='09_PARAMETRI'!$B$8)*('15_NPS'!$F$5:$F$504<>""))),"") | D26: =IFERROR(IF(OR(B26="",C26=""),"",B26-C26),"") | E26: — | F26: Scor 9-10.
A27: % Detractori | B27: =IFERROR((COUNTIFS('15_NPS'!$B$5:$B$504,">="&'09_PARAMETRI'!$B$5,'15_NPS'!$B$5:$B$504,"<="&'09_PARAMETRI'!$B$6,'15_NPS'!$F$5:$F$504,"<=6"))/(SUMPRODUCT(('15_NPS'!$B$5:$B$504>='09_PARAMETRI'!$B$5)*('15_NPS'!$B$5:$B$504<='09_PARAMETRI'!$B$6)*('15_NPS'!$F$5:$F$504<>""))),"") | C27: =IFERROR((COUNTIFS('15_NPS'!$B$5:$B$504,">="&'09_PARAMETRI'!$B$7,'15_NPS'!$B$5:$B$504,"<="&'09_PARAMETRI'!$B$8,'15_NPS'!$F$5:$F$504,"<=6"))/(SUMPRODUCT(('15_NPS'!$B$5:$B$504>='09_PARAMETRI'!$B$7)*('15_NPS'!$B$5:$B$504<='09_PARAMETRI'!$B$8)*('15_NPS'!$F$5:$F$504<>""))),"") | D27: =IFERROR(IF(OR(B27="",C27=""),"",B27-C27),"") | E27: — | F27: Scor 0-6. Aceștia intră în planul de recuperare.
A28: PLAN
A29: Țintă de venit | B29: =SUMIFS('14_TINTE'!$E$5:$E$304,'14_TINTE'!$A$5:$A$304,">="&'09_PARAMETRI'!$B$5,'14_TINTE'!$A$5:$A$304,"<="&'09_PARAMETRI'!$B$6,'14_TINTE'!$D$5:$D$304,"Venit",'14_TINTE'!$B$5:$B$304,"Companie") | C29: =SUMIFS('14_TINTE'!$E$5:$E$304,'14_TINTE'!$A$5:$A$304,">="&'09_PARAMETRI'!$B$7,'14_TINTE'!$A$5:$A$304,"<="&'09_PARAMETRI'!$B$8,'14_TINTE'!$D$5:$D$304,"Venit",'14_TINTE'!$B$5:$B$304,"Companie") | D29: =IFERROR(IF(OR(B29="",C29=""),"",B29-C29),"") | E29: =IFERROR(IF(OR(C29=0,C29=""),"",(B29-C29)/ABS(C29)),"") | F29: Din 14_TINTE, nivel „Companie”, indicator „Venit”.
A30: Atingere țintă % | B30: =IFERROR(SUMIFS('13_VANZARI'!$H$5:$H$1004,'13_VANZARI'!$A$5:$A$1004,">="&'09_PARAMETRI'!$B$5,'13_VANZARI'!$A$5:$A$1004,"<="&'09_PARAMETRI'!$B$6)/(SUMIFS('14_TINTE'!$E$5:$E$304,'14_TINTE'!$A$5:$A$304,">="&'09_PARAMETRI'!$B$5,'14_TINTE'!$A$5:$A$304,"<="&'09_PARAMETRI'!$B$6,'14_TINTE'!$D$5:$D$304,"Venit",'14_TINTE'!$B$5:$B$304,"Companie")),"") | C30: =IFERROR(SUMIFS('13_VANZARI'!$H$5:$H$1004,'13_VANZARI'!$A$5:$A$1004,">="&'09_PARAMETRI'!$B$7,'13_VANZARI'!$A$5:$A$1004,"<="&'09_PARAMETRI'!$B$8)/(SUMIFS('14_TINTE'!$E$5:$E$304,'14_TINTE'!$A$5:$A$304,">="&'09_PARAMETRI'!$B$7,'14_TINTE'!$A$5:$A$304,"<="&'09_PARAMETRI'!$B$8,'14_TINTE'!$D$5:$D$304,"Venit",'14_TINTE'!$B$5:$B$304,"Companie")),"") | D30: =IFERROR(IF(OR(B30="",C30=""),"",B30-C30),"") | E30: — | F30: Venit realizat / țintă.
A31: Gap față de țintă | B31: =IF((SUMIFS('14_TINTE'!$E$5:$E$304,'14_TINTE'!$A$5:$A$304,">="&'09_PARAMETRI'!$B$5,'14_TINTE'!$A$5:$A$304,"<="&'09_PARAMETRI'!$B$6,'14_TINTE'!$D$5:$D$304,"Venit",'14_TINTE'!$B$5:$B$304,"Companie"))=0,"",(SUMIFS('14_TINTE'!$E$5:$E$304,'14_TINTE'!$A$5:$A$304,">="&'09_PARAMETRI'!$B$5,'14_TINTE'!$A$5:$A$304,"<="&'09_PARAMETRI'!$B$6,'14_TINTE'!$D$5:$D$304,"Venit",'14_TINTE'!$B$5:$B$304,"Companie"))-SUMIFS('13_VANZARI'!$H$5:$H$1004,'13_VANZARI'!$A$5:$A$1004,">="&'09_PARAMETRI'!$B$5,'13_VANZARI'!$A$5:$A$1004,"<="&'09_PARAMETRI'!$B$6)) | C31: =IF((SUMIFS('14_TINTE'!$E$5:$E$304,'14_TINTE'!$A$5:$A$304,">="&'09_PARAMETRI'!$B$7,'14_TINTE'!$A$5:$A$304,"<="&'09_PARAMETRI'!$B$8,'14_TINTE'!$D$5:$D$304,"Venit",'14_TINTE'!$B$5:$B$304,"Companie"))=0,"",(SUMIFS('14_TINTE'!$E$5:$E$304,'14_TINTE'!$A$5:$A$304,">="&'09_PARAMETRI'!$B$7,'14_TINTE'!$A$5:$A$304,"<="&'09_PARAMETRI'!$B$8,'14_TINTE'!$D$5:$D$304,"Venit",'14_TINTE'!$B$5:$B$304,"Companie"))-SUMIFS('13_VANZARI'!$H$5:$H$1004,'13_VANZARI'!$A$5:$A$1004,">="&'09_PARAMETRI'!$B$7,'13_VANZARI'!$A$5:$A$1004,"<="&'09_PARAMETRI'!$B$8)) | D31: =IFERROR(IF(OR(B31="",C31=""),"",B31-C31),"") | E31: =IFERROR(IF(OR(C31=0,C31=""),"",(B31-C31)/ABS(C31)),"") | F31: Cât mai lipsește. Acesta e punctul de plecare al oportunităților.

Sheet 21_ANALIZA_CLIENTI
A1: 21 — ANALIZA CLIENȚILOR
A2: Se completează singură din 10_CLIENTI + 13_VANZARI. Filtrează coloana „Semnal” ca să vezi unde e treabă de făcut.
A4: ID client | B4: Denumire client | C4: Segment | D4: Responsabil cont | E4: Venit — perioada curentă | F4: Venit — comparativ | G4: Δ venit % | H4: Profit brut | I4: Marjă % | J4: % din venit total | K4: Ultima achiziție | L4: Zile de la ultima achiziție | M4: Nr. produse cumpărate | N4: NPS mediu | O4: Semnal | P4: Oportunitate sugerată | Q4: Potențial estimat | R4: Cheie clasament
A5: =IF('10_CLIENTI'!$A5="","",'10_CLIENTI'!$A5) | B5: =IF($A5="","",IFERROR(INDEX('10_CLIENTI'!$B$5:$B$204,MATCH($A5,'10_CLIENTI'!$A$5:$A$204,0)),"")) | C5: =IF($A5="","",IFERROR(INDEX('10_CLIENTI'!$C$5:$C$204,MATCH($A5,'10_CLIENTI'!$A$5:$A$204,0)),"")) | D5: =IF($A5="","",IFERROR(INDEX('10_CLIENTI'!$G$5:$G$204,MATCH($A5,'10_CLIENTI'!$A$5:$A$204,0)),"")) | E5: =IF($A5="","",SUMIFS('13_VANZARI'!$H$5:$H$1004,'13_VANZARI'!$D$5:$D$1004,$A5,'13_VANZARI'!$A$5:$A$1004,">="&'09_PARAMETRI'!$B$5,'13_VANZARI'!$A$5:$A$1004,"<="&'09_PARAMETRI'!$B$6)) | F5: =IF($A5="","",SUMIFS('13_VANZARI'!$H$5:$H$1004,'13_VANZARI'!$D$5:$D$1004,$A5,'13_VANZARI'!$A$5:$A$1004,">="&'09_PARAMETRI'!$B$7,'13_VANZARI'!$A$5:$A$1004,"<="&'09_PARAMETRI'!$B$8)) | G5: =IF($A5="","",IFERROR(IF($F5=0,"",($E5-$F5)/ABS($F5)),"")) | H5: =IF($A5="","",SUMIFS('13_VANZARI'!$K$5:$K$1004,'13_VANZARI'!$D$5:$D$1004,$A5,'13_VANZARI'!$A$5:$A$1004,">="&'09_PARAMETRI'!$B$5,'13_VANZARI'!$A$5:$A$1004,"<="&'09_PARAMETRI'!$B$6)) | I5: =IF($A5="","",IFERROR($H5/$E5,"")) | J5: =IF($A5="","",IFERROR($E5/SUMIFS('13_VANZARI'!$H$5:$H$1004,'13_VANZARI'!$A$5:$A$1004,">="&'09_PARAMETRI'!$B$5,'13_VANZARI'!$A$5:$A$1004,"<="&'09_PARAMETRI'!$B$6),"")) | K5: =IF($A5="","",IFERROR(IF(SUMPRODUCT(MAX(('13_VANZARI'!$D$5:$D$1004=$A5)*('13_VANZARI'!$H$5:$H$1004<>"")*'13_VANZARI'!$A$5:$A$1004))=0,"",SUMPRODUCT(MAX(('13_VANZARI'!$D$5:$D$1004=$A5)*('13_VANZARI'!$H$5:$H$1004<>"")*'13_VANZARI'!$A$5:$A$1004))),"")) | L5: =IF(OR($A5="",$K5=""),"",'09_PARAMETRI'!$B$9-$K5) | M5: =IF($A5="","",SUMPRODUCT(('11_PRODUSE'!$A$5:$A$104<>"")*(SUMIFS('13_VANZARI'!$H$5:$H$1004,'13_VANZARI'!$D$5:$D$1004,$A5,'13_VANZARI'!$E$5:$E$1004,'11_PRODUSE'!$A$5:$A$104,'13_VANZARI'!$A$5:$A$1004,">="&'09_PARAMETRI'!$B$5,'13_VANZARI'!$A$5:$A$1004,"<="&'09_PARAMETRI'!$B$6)<>0))) | N5: =IF($A5="","",IFERROR(AVERAGEIFS('15_NPS'!$F$5:$F$504,'15_NPS'!$C$5:$C$504,$A5,'15_NPS'!$B$5:$B$504,">="&'09_PARAMETRI'!$B$5,'15_NPS'!$B$5:$B$504,"<="&'09_PARAMETRI'!$B$6),"")) | O5: =IF($A5="","",IF(AND($F5>0,$E5=0),"Client pierdut",IF(AND($L5<>"",$L5>'09_PARAMETRI'!$B$16,$F5>0),"Client dormant",IF(AND($G5<>"",$G5<='09_PARAMETRI'!$B$13),"Scădere de venit",IF(AND($N5<>"",$N5<7),"Detractor activ",IF(AND($E5>0,$J5>'09_PARAMETRI'!$B$19),"Risc concentrare",IF(AND($E5>0,$I5<>"",$I5<'09_PARAMETRI'!$B$15),"Marjă sub referință",IF(AND($G5<>"",$G5>='09_PARAMETRI'!$B$14),"În creștere",IF($E5=0,"Fără activitate","Stabil"))))))))) | P5: =IF($A5="","",IF($O5="Risc concentrare","Risc concentrare",IF($O5="Client pierdut","Recuperare client",IF($O5="Client dormant","Reactivare client",IF($O5="Scădere de venit","Recuperare client",IF($O5="Detractor activ","Recuperare NPS",IF($O5="Marjă sub referință","Marjă / preț",IF($O5="În creștere","Up-sell",IF($O5="Fără activitate","Reactivare client","Cross-sell"))))))))) | Q5: =IF($A5="","",IFERROR(IF($O5="Scădere de venit",MAX(0,$F5-$E5),IF(OR($O5="Client pierdut",$O5="Client dormant",$O5="Fără activitate"),$F5,IF($O5="Marjă sub referință",MAX(0,$E5*('09_PARAMETRI'!$B$15-$I5)),$E5*0.15))),"")) | R5: =IF(OR($A5="",$E5="",N($E5)<=0),"",$E5+ROW()/1000000)
A6: =IF('10_CLIENTI'!$A6="","",'10_CLIENTI'!$A6) | B6: =IF($A6="","",IFERROR(INDEX('10_CLIENTI'!$B$5:$B$204,MATCH($A6,'10_CLIENTI'!$A$5:$A$204,0)),"")) | C6: =IF($A6="","",IFERROR(INDEX('10_CLIENTI'!$C$5:$C$204,MATCH($A6,'10_CLIENTI'!$A$5:$A$204,0)),"")) | D6: =IF($A6="","",IFERROR(INDEX('10_CLIENTI'!$G$5:$G$204,MATCH($A6,'10_CLIENTI'!$A$5:$A$204,0)),"")) | E6: =IF($A6="","",SUMIFS('13_VANZARI'!$H$5:$H$1004,'13_VANZARI'!$D$5:$D$1004,$A6,'13_VANZARI'!$A$5:$A$1004,">="&'09_PARAMETRI'!$B$5,'13_VANZARI'!$A$5:$A$1004,"<="&'09_PARAMETRI'!$B$6)) | F6: =IF($A6="","",SUMIFS('13_VANZARI'!$H$5:$H$1004,'13_VANZARI'!$D$5:$D$1004,$A6,'13_VANZARI'!$A$5:$A$1004,">="&'09_PARAMETRI'!$B$7,'13_VANZARI'!$A$5:$A$1004,"<="&'09_PARAMETRI'!$B$8)) | G6: =IF($A6="","",IFERROR(IF($F6=0,"",($E6-$F6)/ABS($F6)),"")) | H6: =IF($A6="","",SUMIFS('13_VANZARI'!$K$5:$K$1004,'13_VANZARI'!$D$5:$D$1004,$A6,'13_VANZARI'!$A$5:$A$1004,">="&'09_PARAMETRI'!$B$5,'13_VANZARI'!$A$5:$A$1004,"<="&'09_PARAMETRI'!$B$6)) | I6: =IF($A6="","",IFERROR($H6/$E6,"")) | J6: =IF($A6="","",IFERROR($E6/SUMIFS('13_VANZARI'!$H$5:$H$1004,'13_VANZARI'!$A$5:$A$1004,">="&'09_PARAMETRI'!$B$5,'13_VANZARI'!$A$5:$A$1004,"<="&'09_PARAMETRI'!$B$6),"")) | K6: =IF($A6="","",IFERROR(IF(SUMPRODUCT(MAX(('13_VANZARI'!$D$5:$D$1004=$A6)*('13_VANZARI'!$H$5:$H$1004<>"")*'13_VANZARI'!$A$5:$A$1004))=0,"",SUMPRODUCT(MAX(('13_VANZARI'!$D$5:$D$1004=$A6)*('13_VANZARI'!$H$5:$H$1004<>"")*'13_VANZARI'!$A$5:$A$1004))),"")) | L6: =IF(OR($A6="",$K6=""),"",'09_PARAMETRI'!$B$9-$K6) | M6: =IF($A6="","",SUMPRODUCT(('11_PRODUSE'!$A$5:$A$104<>"")*(SUMIFS('13_VANZARI'!$H$5:$H$1004,'13_VANZARI'!$D$5:$D$1004,$A6,'13_VANZARI'!$E$5:$E$1004,'11_PRODUSE'!$A$5:$A$104,'13_VANZARI'!$A$5:$A$1004,">="&'09_PARAMETRI'!$B$5,'13_VANZARI'!$A$5:$A$1004,"<="&'09_PARAMETRI'!$B$6)<>0))) | N6: =IF($A6="","",IFERROR(AVERAGEIFS('15_NPS'!$F$5:$F$504,'15_NPS'!$C$5:$C$504,$A6,'15_NPS'!$B$5:$B$504,">="&'09_PARAMETRI'!$B$5,'15_NPS'!$B$5:$B$504,"<="&'09_PARAMETRI'!$B$6),"")) | O6: =IF($A6="","",IF(AND($F6>0,$E6=0),"Client pierdut",IF(AND($L6<>"",$L6>'09_PARAMETRI'!$B$16,$F6>0),"Client dormant",IF(AND($G6<>"",$G6<='09_PARAMETRI'!$B$13),"Scădere de venit",IF(AND($N6<>"",$N6<7),"Detractor activ",IF(AND($E6>0,$J6>'09_PARAMETRI'!$B$19),"Risc concentrare",IF(AND($E6>0,$I6<>"",$I6<'09_PARAMETRI'!$B$15),"Marjă sub referință",IF(AND($G6<>"",$G6>='09_PARAMETRI'!$B$14),"În creștere",IF($E6=0,"Fără activitate","Stabil"))))))))) | P6: =IF($A6="","",IF($O6="Risc concentrare","Risc concentrare",IF($O6="Client pierdut","Recuperare client",IF($O6="Client dormant","Reactivare client",IF($O6="Scădere de venit","Recuperare client",IF($O6="Detractor activ","Recuperare NPS",IF($O6="Marjă sub referință","Marjă / preț",IF($O6="În creștere","Up-sell",IF($O6="Fără activitate","Reactivare client","Cross-sell"))))))))) | Q6: =IF($A6="","",IFERROR(IF($O6="Scădere de venit",MAX(0,$F6-$E6),IF(OR($O6="Client pierdut",$O6="Client dormant",$O6="Fără activitate"),$F6,IF($O6="Marjă sub referință",MAX(0,$E6*('09_PARAMETRI'!$B$15-$I6)),$E6*0.15))),"")) | R6: =IF(OR($A6="",$E6="",N($E6)<=0),"",$E6+ROW()/1000000)
